Workbook

Sheet EKİM 2026 
A2: SATIŞ | B2: NAKİT SATIŞ | C2: KREDİ SATIŞ | D2: Z RAPORU NAKİT | E2: Z RAPORU KREDİ | F2: YATACAK OLAN | G2: NAKİT FARK | H2: KREDİ FARK | I2: KDV | J2: NAKİT HARCAMA | K2: KREDİ HARCAMA | L2: CİRO | M2: CEP NAKİT | N2: CEP KREDİ
A3: 46296 | B3: 1050 | C3: 5820 | D3: 0 | E3: 5820 | F3: =+E3-(E3*3.99/100) -> 5587.782 | G3: =SUM(D3-B3) -> -1050 | H3: =SUM(E3-C3) -> 0 | I3: =+C3*2/12 -> 970 | J3: 350 | K3: 0 | L3: =+E3+B3 -> 6870 | M3: =SUM(B3-J3) -> 700 | N3: =SUM(E3-K3) -> 5820
A4: =+A3+1 -> 46297 | B4: 2100 | C4: 2950 | D4: 0 | E4: 2950 | F4: =+E4-(E4*3.99/100) -> 2832.295 | G4: =SUM(D4-B4) -> -2100 | H4: =SUM(E4-C4) -> 0 | I4: =+C4*2/12 -> 491.66667 | J4: 145 | K4: 1130 | L4: =+E4+B4 -> 5050 | M4: =SUM(B4-J4) -> 1955 | N4: =SUM(E4-K4) -> 1820
A5: =+A4+1 -> 46298 | B5: 1050 | C5: 6860 | D5: 0 | E5: 6860 | F5: =+E5-(E5*3.99/100) -> 6586.286 | G5: =SUM(D5-B5) -> -1050 | H5: =SUM(E5-C5) -> 0 | I5: =+C5*2/12 -> 1143.3333 | J5: 100 | K5: 0 | L5: =+E5+B5 -> 7910 | M5: =SUM(B5-J5) -> 950 | N5: =SUM(E5-K5) -> 6860
A6: =+A5+1 -> 46299 | B6: 200 | C6: 3010 | D6: 0 | E6: 3010 | F6: =+E6-(E6*3.99/100) -> 2889.901 | G6: =SUM(D6-B6) -> -200 | H6: =SUM(E6-C6) -> 0 | I6: =+C6*2/12 -> 501.66667 | J6: 300 | K6: 0 | L6: =+E6+B6 -> 3210 | M6: =SUM(B6-J6) -> -100 | N6: =SUM(E6-K6) -> 3010
A7: =+A6+1 -> 46300 | B7: 200 | C7: 1050 | D7: 0 | E7: 1050 | F7: =+E7-(E7*3.99/100) -> 1008.105 | G7: =SUM(D7-B7) -> -200 | H7: =SUM(E7-C7) -> 0 | I7: =+C7*2/12 -> 175 | J7: 0 | K7: 16420 | L7: =+E7+B7 -> 1250 | M7: =SUM(B7-J7) -> 200 | N7: =SUM(E7-K7) -> -15370
A8: =+A7+1 -> 46301 | B8: 800 | C8: 6200 | D8: 0 | E8: 6220 | F8: =+E8-(E8*3.99/100) -> 5971.822 | G8: =SUM(D8-B8) -> -800 | H8: =SUM(E8-C8) -> 20 | I8: =+C8*2/12 -> 1033.3333 | J8: 0 | K8: 0 | L8: =+E8+B8 -> 7020 | M8: 0 | N8: =SUM(E8-K8) -> 6220
A9: =+A8+1 -> 46302 | B9: 550 | C9: 1750 | D9: 0 | E9: 1750 | F9: =+E9-(E9*3.99/100) -> 1680.175 | G9: =SUM(D9-B9) -> -550 | H9: =SUM(E9-C9) -> 0 | I9: =+C9*2/12 -> 291.66667 | J9: 3000 | K9: 0 | L9: =+E9+B9 -> 2300 | M9: =SUM(B9-J9) -> -2450 | N9: =SUM(E9-K9) -> 1750
A10: =+A9+1 -> 46303 | F10: =+E10-(E10*3.99/100) -> 0 | G10: =SUM(D10-B10) -> 0 | H10: =SUM(E10-C10) -> 0 | J10: 3300 | K10: 13450 | L10: =+E10+B10 -> 0 | M10: =SUM(B10-J10) -> -3300 | N10: =SUM(E10-K10) -> -13450
A11: =+A10+1 -> 46304 | F11: =+E11-(E11*3.99/100) -> 0 | G11: =SUM(D11-B11) -> 0 | H11: =SUM(E11-C11) -> 0 | L11: =+E11+B11 -> 0 | M11: =SUM(B11-J11) -> 0 | N11: =SUM(E11-K11) -> 0
A12: =+A11+1 -> 46305 | F12: =+E12-(E12*3.99/100) -> 0 | G12: =SUM(D12-B12) -> 0 | H12: =SUM(E12-C12) -> 0 | L12: =+E12+B12 -> 0 | M12: =SUM(B12-J12) -> 0 | N12: =SUM(E12-K12) -> 0
A13: =+A12+1 -> 46306 | F13: =+E13-(E13*3.99/100) -> 0 | G13: =SUM(D13-B13) -> 0 | H13: =SUM(E13-C13) -> 0 | L13: =+E13+B13 -> 0 | M13: =SUM(B13-J13) -> 0 | N13: =SUM(E13-K13) -> 0
A14: =+A13+1 -> 46307 | F14: =+E14-(E14*3.99/100) -> 0 | G14: =SUM(D14-B14) -> 0 | H14: =SUM(E14-C14) -> 0 | L14: =+E14+B14 -> 0 | M14: =SUM(B14-J14) -> 0 | N14: =SUM(E14-K14) -> 0
A15: =+A14+1 -> 46308 | F15: =+E15-(E15*3.99/100) -> 0 | G15: =SUM(D15-B15) -> 0 | H15: =SUM(E15-C15) -> 0 | L15: =+E15+B15 -> 0 | M15: =SUM(B15-J15) -> 0 | N15: =SUM(E15-K15) -> 0
A16: =+A15+1 -> 46309 | F16: =+E16-(E16*3.99/100) -> 0 | G16: =SUM(D16-B16) -> 0 | H16: =SUM(E16-C16) -> 0 | L16: =+E16+B16 -> 0 | M16: =SUM(B16-J16) -> 0 | N16: =SUM(E16-K16) -> 0
A17: =+A16+1 -> 46310 | F17: =+E17-(E17*3.99/100) -> 0 | G17: =SUM(D17-B17) -> 0 | H17: =SUM(E17-C17) -> 0 | L17: =+E17+B17 -> 0 | M17: =SUM(B17-J17) -> 0 | N17: =SUM(E17-K17) -> 0
A18: =+A17+1 -> 46311 | F18: =+E18-(E18*3.99/100) -> 0 | G18: =SUM(D18-B18) -> 0 | H18: =SUM(E18-C18) -> 0 | L18: =+E18+B18 -> 0 | M18: =SUM(B18-J18) -> 0 | N18: =SUM(E18-K18) -> 0
A19: =+A18+1 -> 46312 | F19: =+E19-(E19*3.99/100) -> 0 | G19: =SUM(D19-B19) -> 0 | H19: =SUM(E19-C19) -> 0 | L19: =+E19+B19 -> 0 | M19: =SUM(B19-J19) -> 0 | N19: =SUM(E19-K19) -> 0
A20: =+A19+1 -> 46313 | F20: =+E20-(E20*3.99/100) -> 0 | G20: =SUM(D20-B20) -> 0 | H20: =SUM(E20-C20) -> 0 | L20: =+E20+B20 -> 0 | M20: =SUM(B20-J20) -> 0 | N20: =SUM(E20-K20) -> 0
A21: =+A20+1 -> 46314 | F21: =+E21-(E21*3.99/100) -> 0 | G21: =SUM(D21-B21) -> 0 | H21: =SUM(E21-C21) -> 0 | L21: =+E21+B21 -> 0 | M21: =SUM(B21-J21) -> 0 | N21: =SUM(E21-K21) -> 0 | R21: 5
A22: =+A21+1 -> 46315 | F22: =+E22-(E22*3.99/100) -> 0 | G22: =SUM(D22-B22) -> 0 | H22: =SUM(E22-C22) -> 0 | L22: =+E22+B22 -> 0 | M22: =SUM(B22-J22) -> 0 | N22: =SUM(E22-K22) -> 0
A23: =+A22+1 -> 46316 | F23: =+E23-(E23*3.99/100) -> 0 | G23: =SUM(D23-B23) -> 0 | H23: =SUM(E23-C23) -> 0 | L23: =+E23+B23 -> 0 | M23: =SUM(B23-J23) -> 0 | N23: =SUM(E23-K23) -> 0
A24: =+A23+1 -> 46317 | F24: =+E24-(E24*3.99/100) -> 0 | G24: =SUM(D24-B24) -> 0 | H24: =SUM(E24-C24) -> 0 | L24: =+E24+B24 -> 0 | M24: =SUM(B24-J24) -> 0 | N24: =SUM(E24-K24) -> 0
A25: =+A24+1 -> 46318 | F25: =+E25-(E25*3.99/100) -> 0 | G25: =SUM(D25-B25) -> 0 | H25: =SUM(E25-C25) -> 0 | L25: =+E25+B25 -> 0 | M25: =SUM(B25-J25) -> 0 | N25: =SUM(E25-K25) -> 0
A26: =+A25+1 -> 46319 | F26: =+E26-(E26*3.99/100) -> 0 | G26: =SUM(D26-B26) -> 0 | H26: =SUM(E26-C26) -> 0 | L26: =+E26+B26 -> 0 | M26: =SUM(B26-J26) -> 0 | N26: =SUM(E26-K26) -> 0
A27: =+A26+1 -> 46320 | F27: =+E27-(E27*3.99/100) -> 0 | G27: =SUM(D27-B27) -> 0 | H27: =SUM(E27-C27) -> 0 | L27: =+E27+B27 -> 0 | M27: =SUM(B27-J27) -> 0 | N27: =SUM(E27-K27) -> 0
A28: =+A27+1 -> 46321 | F28: =+E28-(E28*3.99/100) -> 0 | G28: =SUM(D28-B28) -> 0 | H28: =SUM(E28-C28) -> 0 | L28: =+E28+B28 -> 0 | M28: =SUM(B28-J28) -> 0 | N28: =SUM(E28-K28) -> 0
A29: =+A28+1 -> 46322 | F29: =+E29-(E29*3.99/100) -> 0 | G29: =SUM(D29-B29) -> 0 | H29: =SUM(E29-C29) -> 0 | L29: =+E29+B29 -> 0 | M29: =SUM(B29-J29) -> 0 | N29: =SUM(E29-K29) -> 0
A30: =+A29+1 -> 46323 | F30: =+E30-(E30*3.99/100) -> 0 | G30: =SUM(D30-B30) -> 0 | H30: =SUM(E30-C30) -> 0 | L30: =+E30+B30 -> 0 | M30: =SUM(B30-J30) -> 0 | N30: =SUM(E30-K30) -> 0
A31: =+A30+1 -> 46324 | F31: =+E31-(E31*3.99/100) -> 0 | G31: =SUM(D31-B31) -> 0 | H31: =SUM(E31-C31) -> 0 | L31: =+E31+B31 -> 0 | M31: =SUM(B31-J31) -> 0 | N31: =SUM(E31-K31) -> 0
A32: =+A31+1 -> 46325 | F32: =+E32-(E32*3.99/100) -> 0 | G32: =SUM(D32-B32) -> 0 | H32: =SUM(E32-C32) -> 0 | L32: =+E32+B32 -> 0 | M32: =SUM(B32-J32) -> 0 | N32: =SUM(E32-K32) -> 0
A33: =+A32+1 -> 46326 | F33: =+E33-(E33*3.99/100) -> 0 | G33: =SUM(D33-B33) -> 0 | H33: =SUM(E33-C33) -> 0 | L33: =+E33+B33 -> 0 | M33: =SUM(B33-J33) -> 0 | N33: =SUM(E33-K33) -> 0
A34: TOPLAM | B34: =SUM(B3:B33) -> 5950 | C34: =SUM(C3:C33) -> 27640 | D34: =SUM(D3:D33) -> 0 | E34: =SUM(E3:E33) -> 27660 | F34: =+E34-(E34*3.99/100) -> 26556.366 | G34: =SUM(G3:G32) -> -5950 | H34: =SUM(H3:H32) -> 20 | I34: =SUM(I3:I33) -> 4606.6667 | J34: =SUM(J3:J33) -> 7195 | L34: =SUM(L3:L32) -> 33610 | M34: =SUM(M3:M32) -> -2045 | N34: =SUM(N3:N32) -> -3340
F35: =+E34-F34 -> 1103.634 | L35: =AVERAGE(L3:L32) -> 1120.3333
H37: TOPLAM CİRO | J37: =SUM(L3:L32) -> 33610
H38: TOPLAM HARCAMA | J38: =SUM(+J34+K34) -> 7195
H39: TOPLAM CİRODAN KALAN | J39: =SUM(M34+N34) -> -5385

Sheet EYLÜL 2026
A2: SATIŞ | B2: NAKİT SATIŞ | C2: KREDİ SATIŞ | D2: Z RAPORU NAKİT | E2: Z RAPORU KREDİ | F2: YATACAK OLAN | G2: NAKİT FARK | H2: KREDİ FARK | I2: KDV | J2: NAKİT HARCAMA | K2: KREDİ HARCAMA | L2: CİRO | M2: CEP NAKİT | N2: CEP KREDİ
A3: 46266 | B3: 0 | C3: 2790 | D3: 0 | E3: 2790 | F3: =+E3-(E3*3.99/100) -> 2678.679 | G3: =SUM(D3-B3) -> 0 | H3: =SUM(E3-C3) -> 0 | I3: =+C3*2/12 -> 465 | J3: 0 | K3: 0 | L3: =+E3+B3 -> 2790 | M3: =SUM(B3-J3) -> 0 | N3: =SUM(E3-K3) -> 2790
A4: =+A3+1 -> 46267 | B4: 1000 | C4: 2400 | D4: 0 | E4: 2400 | F4: =+E4-(E4*3.99/100) -> 2304.24 | G4: =SUM(D4-B4) -> -1000 | H4: =SUM(E4-C4) -> 0 | I4: =+C4*2/12 -> 400 | J4: 0 | K4: 0 | L4: =+E4+B4 -> 3400 | M4: =SUM(B4-J4) -> 1000 | N4: =SUM(E4-K4) -> 2400
A5: =+A4+1 -> 46268 | B5: 3650 | C5: 2680 | D5: 0 | E5: 2680 | F5: =+E5-(E5*3.99/100) -> 2573.068 | G5: =SUM(D5-B5) -> -3650 | H5: =SUM(E5-C5) -> 0 | I5: =+C5*2/12 -> 446.66667 | J5: 190 | K5: 260 | L5: =+E5+B5 -> 6330 | M5: =SUM(B5-J5) -> 3460 | N5: =SUM(E5-K5) -> 2420
A6: =+A5+1 -> 46269 | B6: 1300 | C6: 1050 | D6: 0 | E6: 1050 | F6: =+E6-(E6*3.99/100) -> 1008.105 | G6: =SUM(D6-B6) -> -1300 | H6: =SUM(E6-C6) -> 0 | I6: =+C6*2/12 -> 175 | J6: 0 | K6: 0 | L6: =+E6+B6 -> 2350 | M6: =SUM(B6-J6) -> 1300 | N6: =SUM(E6-K6) -> 1050
A7: =+A6+1 -> 46270 | B7: 850 | C7: 3640 | D7: 0 | E7: 3640 | F7: =+E7-(E7*3.99/100) -> 3494.764 | G7: =SUM(D7-B7) -> -850 | H7: =SUM(E7-C7) -> 0 | I7: =+C7*2/12 -> 606.66667 | J7: 0 | K7: 1710 | L7: =+E7+B7 -> 4490 | M7: =SUM(B7-J7) -> 850 | N7: =SUM(E7-K7) -> 1930
A8: =+A7+1 -> 46271 | B8: 1450 | C8: 4300 | D8: 0 | E8: 4300 | F8: =+E8-(E8*3.99/100) -> 4128.43 | G8: =SUM(D8-B8) -> -1450 | H8: =SUM(E8-C8) -> 0 | I8: =+C8*2/12 -> 716.66667 | J8: 230 | K8: 140 | L8: =+E8+B8 -> 5750 | M8: 0 | N8: =SUM(E8-K8) -> 4160
A9: =+A8+1 -> 46272 | B9: 500 | C9: 1300 | D9: 0 | E9: 1300 | F9: =+E9-(E9*3.99/100) -> 1248.13 | G9: =SUM(D9-B9) -> -500 | H9: =SUM(E9-C9) -> 0 | I9: =+C9*2/12 -> 216.66667 | J9: 11270 | K9: 34690 | L9: =+E9+B9 -> 1800 | M9: =SUM(B9-J9) -> -10770 | N9: =SUM(E9-K9) -> -33390
A10: =+A9+1 -> 46273 | B10: 0 | C10: 4540 | D10: 0 | E10: 4540 | F10: =+E10-(E10*3.99/100) -> 4358.854 | G10: =SUM(D10-B10) -> 0 | H10: =SUM(E10-C10) -> 0 | I10: =+C10*2/12 -> 756.66667 | J10: 0 | K10: 0 | L10: =+E10+B10 -> 4540 | M10: =SUM(B10-J10) -> 0 | N10: =SUM(E10-K10) -> 4540
A11: =+A10+1 -> 46274 | B11: 1200 | C11: 3880 | D11: 0 | E11: 3880 | F11: =+E11-(E11*3.99/100) -> 3725.188 | G11: =SUM(D11-B11) -> -1200 | H11: =SUM(E11-C11) -> 0 | I11: =+C11*2/12 -> 646.66667 | J11: 0 | K11: 360 | L11: =+E11+B11 -> 5080 | M11: =SUM(B11-J11) -> 1200 | N11: =SUM(E11-K11) -> 3520
A12: =+A11+1 -> 46275 | B12: 1800 | C12: 3060 | D12: 0 | E12: 3060 | F12: =+E12-(E12*3.99/100) -> 2937.906 | G12: =SUM(D12-B12) -> -1800 | H12: =SUM(E12-C12) -> 0 | I12: =+C12*2/12 -> 510 | J12: 0 | K12: 3000 | L12: =+E12+B12 -> 4860 | M12: =SUM(B12-J12) -> 1800 | N12: =SUM(E12-K12) -> 60
A13: =+A12+1 -> 46276 | B13: 600 | C13: 4425 | D13: 0 | E13: 4425 | F13: =+E13-(E13*3.99/100) -> 4248.4425 | G13: =SUM(D13-B13) -> -600 | H13: =SUM(E13-C13) -> 0 | I13: =+C13*2/12 -> 737.5 | J13: 150 | K13: 1980 | L13: =+E13+B13 -> 5025 | M13: =SUM(B13-J13) -> 450 | N13: =SUM(E13-K13) -> 2445
A14: =+A13+1 -> 46277 | B14: 1240 | C14: 3440 | D14: 0 | E14: 3440 | F14: =+E14-(E14*3.99/100) -> 3302.744 | G14: =SUM(D14-B14) -> -1240 | H14: =SUM(E14-C14) -> 0 | I14: =+C14*2/12 -> 573.33333 | J14: 600 | K14: 0 | L14: =+E14+B14 -> 4680 | M14: =SUM(B14-J14) -> 640 | N14: =SUM(E14-K14) -> 3440
A15: =+A14+1 -> 46278 | B15: 300 | C15: 1100 | D15: 0 | E15: 1100 | F15: =+E15-(E15*3.99/100) -> 1056.11 | G15: =SUM(D15-B15) -> -300 | H15: =SUM(E15-C15) -> 0 | I15: =+C15*2/12 -> 183.33333 | J15: 200 | K15: 0 | L15: =+E15+B15 -> 1400 | M15: =SUM(B15-J15) -> 100 | N15: =SUM(E15-K15) -> 1100
A16: =+A15+1 -> 46279 | B16: 0 | C16: 1925 | D16: 0 | E16: 1925 | F16: =+E16-(E16*3.99/100) -> 1848.1925 | G16: =SUM(D16-B16) -> 0 | H16: =SUM(E16-C16) -> 0 | I16: =+C16*2/12 -> 320.83333 | J16: 0 | K16: 0 | L16: =+E16+B16 -> 1925 | M16: =SUM(B16-J16) -> 0 | N16: =SUM(E16-K16) -> 1925
A17: =+A16+1 -> 46280 | B17: 400 | C17: 3040 | D17: 0 | E17: 3040 | F17: =+E17-(E17*3.99/100) -> 2918.704 | G17: =SUM(D17-B17) -> -400 | H17: =SUM(E17-C17) -> 0 | I17: =+C17*2/12 -> 506.66667 | J17: 3400 | K17: 27100 | L17: =+E17+B17 -> 3440 | M17: =SUM(B17-J17) -> -3000 | N17: =SUM(E17-K17) -> -24060
A18: =+A17+1 -> 46281 | B18: 1500 | C18: 650 | D18: 0 | E18: 650 | F18: =+E18-(E18*3.99/100) -> 624.065 | G18: =SUM(D18-B18) -> -1500 | H18: =SUM(E18-C18) -> 0 | I18: =+C18*2/12 -> 108.33333 | J18: 450 | K18: 0 | L18: =+E18+B18 -> 2150 | M18: =SUM(B18-J18) -> 1050 | N18: =SUM(E18-K18) -> 650
A19: =+A18+1 -> 46282 | B19: 2600 | C19: 4080 | D19: 0 | E19: 4080 | F19: =+E19-(E19*3.99/100) -> 3917.208 | G19: =SUM(D19-B19) -> -2600 | H19: =SUM(E19-C19) -> 0 | I19: =+C19*2/12 -> 680 | J19: 0 | K19: 0 | L19: =+E19+B19 -> 6680 | M19: =SUM(B19-J19) -> 2600 | N19: =SUM(E19-K19) -> 4080
A20: =+A19+1 -> 46283 | B20: 0 | C20: 4020 | D20: 0 | E20: 4020 | F20: =+E20-(E20*3.99/100) -> 3859.602 | G20: =SUM(D20-B20) -> 0 | H20: =SUM(E20-C20) -> 0 | I20: =+C20*2/12 -> 670 | J20: 100 | K20: 0 | L20: =+E20+B20 -> 4020 | M20: =SUM(B20-J20) -> -100 | N20: =SUM(E20-K20) -> 4020
A21: =+A20+1 -> 46284 | B21: 1200 | C21: 4270 | D21: 0 | E21: 4270 | F21: =+E21-(E21*3.99/100) -> 4099.627 | G21: =SUM(D21-B21) -> -1200 | H21: =SUM(E21-C21) -> 0 | I21: =+C21*2/12 -> 711.66667 | J21: 0 | K21: 0 | L21: =+E21+B21 -> 5470 | M21: =SUM(B21-J21) -> 1200 | N21: =SUM(E21-K21) -> 4270 | R21: 5
A22: =+A21+1 -> 46285 | B22: 550 | C22: 2170 | D22: 0 | E22: 2170 | F22: =+E22-(E22*3.99/100) -> 2083.417 | G22: =SUM(D22-B22) -> -550 | H22: =SUM(E22-C22) -> 0 | I22: =+C22*2/12 -> 361.66667 | J22: 0 | K22: 0 | L22: =+E22+B22 -> 2720 | M22: =SUM(B22-J22) -> 550 | N22: =SUM(E22-K22) -> 2170
A23: =+A22+1 -> 46286 | B23: 300 | C23: 6000 | D23: 0 | E23: 6000 | F23: =+E23-(E23*3.99/100) -> 5760.6 | G23: =SUM(D23-B23) -> -300 | H23: =SUM(E23-C23) -> 0 | I23: =+C23*2/12 -> 1000 | J23: 1700 | K23: 100 | L23: =+E23+B23 -> 6300 | M23: =SUM(B23-J23) -> -1400 | N23: =SUM(E23-K23) -> 5900
A24: =+A23+1 -> 46287 | B24: 350 | C24: 7040 | D24: 0 | E24: 7040 | F24: =+E24-(E24*3.99/100) -> 6759.104 | G24: =SUM(D24-B24) -> -350 | H24: =SUM(E24-C24) -> 0 | I24: =+C24*2/12 -> 1173.3333 | J24: 0 | K24: 0 | L24: =+E24+B24 -> 7390 | M24: =SUM(B24-J24) -> 350 | N24: =SUM(E24-K24) -> 7040
A25: =+A24+1 -> 46288 | B25: 1200 | C25: 3200 | D25: 0 | E25: 3200 | F25: =+E25-(E25*3.99/100) -> 3072.32 | G25: =SUM(D25-B25) -> -1200 | H25: =SUM(E25-C25) -> 0 | I25: =+C25*2/12 -> 533.33333 | J25: 350 | K25: 16000 | L25: =+E25+B25 -> 4400 | M25: =SUM(B25-J25) -> 850 | N25: =SUM(E25-K25) -> -12800
A26: =+A25+1 -> 46289 | B26: 200 | C26: 70 | D26: 0 | E26: 70 | F26: =+E26-(E26*3.99/100) -> 67.207 | G26: =SUM(D26-B26) -> -200 | H26: =SUM(E26-C26) -> 0 | I26: =+C26*2/12 -> 11.666667 | J26: 4100 | K26: 29000 | L26: =+E26+B26 -> 270 | M26: =SUM(B26-J26) -> -3900 | N26: =SUM(E26-K26) -> -28930
A27: =+A26+1 -> 46290 | B27: 1000 | C27: 1830 | D27: 0 | E27: 1830 | F27: =+E27-(E27*3.99/100) -> 1756.983 | G27: =SUM(D27-B27) -> -1000 | H27: =SUM(E27-C27) -> 0 | I27: =+C27*2/12 -> 305 | J27: 0 | K27: 0 | L27: =+E27+B27 -> 2830 | M27: =SUM(B27-J27) -> 1000 | N27: =SUM(E27-K27) -> 1830
A28: =+A27+1 -> 46291 | B28: 2600 | C28: 3930 | D28: 0 | E28: 3930 | F28: =+E28-(E28*3.99/100) -> 3773.193 | G28: =SUM(D28-B28) -> -2600 | H28: =SUM(E28-C28) -> 0 | I28: =+C28*2/12 -> 655 | J28: 0 | K28: 0 | L28: =+E28+B28 -> 6530 | M28: =SUM(B28-J28) -> 2600 | N28: =SUM(E28-K28) -> 3930
A29: =+A28+1 -> 46292 | B29: 0 | C29: 0 | D29: 0 | E29: 0 | F29: =+E29-(E29*3.99/100) -> 0 | G29: =SUM(D29-B29) -> 0 | H29: =SUM(E29-C29) -> 0 | I29: =+C29*2/12 -> 0 | J29: 100 | K29: 0 | L29: =+E29+B29 -> 0 | M29: =SUM(B29-J29) -> -100 | N29: =SUM(E29-K29) -> 0
A30: =+A29+1 -> 46293 | B30: 1550 | C30: 4950 | D30: 0 | E30: 4950 | F30: =+E30-(E30*3.99/100) -> 4752.495 | G30: =SUM(D30-B30) -> -1550 | H30: =SUM(E30-C30) -> 0 | I30: =+C30*2/12 -> 825 | J30: 4800 | K30: 5500 | L30: =+E30+B30 -> 6500 | M30: =SUM(B30-J30) -> -3250 | N30: =SUM(E30-K30) -> -550
A31: =+A30+1 -> 46294 | B31: 1200 | C31: 2640 | D31: 0 | E31: 2640 | F31: =+E31-(E31*3.99/100) -> 2534.664 | G31: =SUM(D31-B31) -> -1200 | H31: =SUM(E31-C31) -> 0 | I31: =+C31*2/12 -> 440 | J31: 0 | K31: 0 | L31: =+E31+B31 -> 3840 | M31: =SUM(B31-J31) -> 1200 | N31: =SUM(E31-K31) -> 2640
A32: =+A31+1 -> 46295 | B32: 100 | C32: 1050 | D32: 0 | E32: 1050 | F32: =+E32-(E32*3.99/100) -> 1008.105 | G32: =SUM(D32-B32) -> -100 | H32: =SUM(E32-C32) -> 0 | I32: =+C32*2/12 -> 175 | J32: 250 | K32: 11820 | L32: =+E32+B32 -> 1150 | M32: =SUM(B32-J32) -> -150 | N32: =SUM(E32-K32) -> -10770
M33: =SUM(B33-J33) -> 0 | N33: =SUM(E33-K33) -> 0
A34: TOPLAM | B34: =SUM(B3:B33) -> 28640 | C34: =SUM(C3:C33) -> 89470 | D34: =SUM(D3:D33) -> 0 | E34: =SUM(E3:E33) -> 89470 | F34: =+E34-(E34*3.99/100) -> 85900.147 | G34: =SUM(G3:G32) -> -28640 | H34: =SUM(H3:H32) -> 0 | I34: =SUM(I3:I32) -> 14911.667 | J34: =SUM(J3:J33) -> 27890 | L34: =SUM(L3:L32) -> 118110 | M34: =SUM(M3:M32) -> -470 | N34: =SUM(N3:N32) -> -42190
E35: KESİNTİ | F35: =+E34-F34 -> 3569.853 | L35: =AVERAGE(L3:L32) -> 3937
H37: TOPLAM CİRO | J37: =SUM(L3:L32) -> 118110
H38: TOPLAM HARCAMA | J38: =SUM(+J34+K34) -> 27890
H39: TOPLAM CİRODAN KALAN | J39: =SUM(M34+N34) -> -42660

Sheet AĞUSTOS 2026
A2: SATIŞ | B2: NAKİT SATIŞ | C2: KREDİ SATIŞ | D2: Z RAPORU NAKİT | E2: Z RAPORU KREDİ | F2: YATACAK OLAN | G2: NAKİT FARK | H2: KREDİ FARK | I2: KDV | J2: NAKİT HARCAMA | K2: KREDİ HARCAMA | L2: CİRO | M2: CEP NAKİT | N2: CEP KREDİ
A3: 46235 | B3: 2200 | C3: 3790 | D3: 0 | E3: 3790 | F3: =+E3-(E3*3.99/100) -> 3638.779 | G3: =SUM(D3-B3) -> -2200 | H3: =SUM(E3-C3) -> 0 | I3: =+C3*2/12 -> 631.66667 | J3: 40 | K3: 60 | L3: =+E3+B3 -> 5990 | M3: =SUM(B3-J3) -> 2160 | N3: =SUM(E3-K3) -> 3730
A4: =+A3+1 -> 46236 | B4: 200 | C4: 4100 | D4: 0 | E4: 4100 | F4: =+E4-(E4*3.99/100) -> 3936.41 | G4: =SUM(D4-B4) -> -200 | H4: =SUM(E4-C4) -> 0 | I4: =+C4*2/12 -> 683.33333 | J4: 200 | K4: 700 | L4: =+E4+B4 -> 4300 | M4: =SUM(B4-J4) -> 0 | N4: =SUM(E4-K4) -> 3400
A5: =+A4+1 -> 46237 | B5: 0 | C5: 1350 | D5: 0 | E5: 1350 | F5: =+E5-(E5*3.99/100) -> 1296.135 | G5: =SUM(D5-B5) -> 0 | H5: =SUM(E5-C5) -> 0 | I5: =+C5*2/12 -> 225 | J5: 600 | K5: 0 | L5: =+E5+B5 -> 1350 | M5: =SUM(B5-J5) -> -600 | N5: =SUM(E5-K5) -> 1350
A6: =+A5+1 -> 46238 | B6: 200 | C6: 1570 | D6: 0 | E6: 1570 | F6: =+E6-(E6*3.99/100) -> 1507.357 | G6: =SUM(D6-B6) -> -200 | H6: =SUM(E6-C6) -> 0 | I6: =+C6*2/12 -> 261.66667 | J6: 350 | K6: 0 | L6: =+E6+B6 -> 1770 | M6: =SUM(B6-J6) -> -150 | N6: =SUM(E6-K6) -> 1570
A7: =+A6+1 -> 46239 | B7: 1600 | C7: 2810 | D7: 0 | E7: 2810 | F7: =+E7-(E7*3.99/100) -> 2697.881 | G7: =SUM(D7-B7) -> -1600 | H7: =SUM(E7-C7) -> 0 | I7: =+C7*2/12 -> 468.33333 | J7: 3000 | K7: 520 | L7: =+E7+B7 -> 4410 | M7: =SUM(B7-J7) -> -1400 | N7: =SUM(E7-K7) -> 2290
A8: =+A7+1 -> 46240 | B8: 1750 | C8: 3970 | D8: 0 | E8: 3970 | F8: =+E8-(E8*3.99/100) -> 3811.597 | G8: =SUM(D8-B8) -> -1750 | H8: =SUM(E8-C8) -> 0 | I8: =+C8*2/12 -> 661.66667 | J8: 155 | K8: 0 | L8: =+E8+B8 -> 5720 | M8: 0 | N8: =SUM(E8-K8) -> 3970
A9: =+A8+1 -> 46241 | B9: 950 | C9: 2030 | D9: 0 | E9: 2030 | F9: =+E9-(E9*3.99/100) -> 1949.003 | G9: =SUM(D9-B9) -> -950 | H9: =SUM(E9-C9) -> 0 | I9: =+C9*2/12 -> 338.33333 | J9: 0 | K9: 230 | L9: =+E9+B9 -> 2980 | M9: =SUM(B9-J9) -> 950 | N9: =SUM(E9-K9) -> 1800
A10: =+A9+1 -> 46242 | B10: 350 | C10: 2020 | D10: 0 | E10: 2020 | F10: =+E10-(E10*3.99/100) -> 1939.402 | G10: =SUM(D10-B10) -> -350 | H10: =SUM(E10-C10) -> 0 | I10: =+C10*2/12 -> 336.66667 | J10: 7500 | K10: 26910 | L10: =+E10+B10 -> 2370 | M10: =SUM(B10-J10) -> -7150 | N10: =SUM(E10-K10) -> -24890
A11: =+A10+1 -> 46243 | B11: 30 | C11: 2050 | D11: 0 | E11: 2050 | F11: =+E11-(E11*3.99/100) -> 1968.205 | G11: =SUM(D11-B11) -> -30 | H11: =SUM(E11-C11) -> 0 | I11: =+C11*2/12 -> 341.66667 | J11: 120 | K11: 0 | L11: =+E11+B11 -> 2080 | M11: =SUM(B11-J11) -> -90 | N11: =SUM(E11-K11) -> 2050
A12: =+A11+1 -> 46244 | B12: 2000 | C12: 1980 | D12: 0 | E12: 1980 | F12: =+E12-(E12*3.99/100) -> 1900.998 | G12: =SUM(D12-B12) -> -2000 | H12: =SUM(E12-C12) -> 0 | I12: =+C12*2/12 -> 330 | J12: 0 | K12: 0 | L12: =+E12+B12 -> 3980 | M12: =SUM(B12-J12) -> 2000 | N12: =SUM(E12-K12) -> 1980
A13: =+A12+1 -> 46245 | B13: 2220 | C13: 3110 | D13: 0 | E13: 3110 | F13: =+E13-(E13*3.99/100) -> 2985.911 | G13: =SUM(D13-B13) -> -2220 | H13: =SUM(E13-C13) -> 0 | I13: =+C13*2/12 -> 518.33333 | J13: 450 | K13: 0 | L13: =+E13+B13 -> 5330 | M13: =SUM(B13-J13) -> 1770 | N13: =SUM(E13-K13) -> 3110
A14: =+A13+1 -> 46246 | B14: 1650 | C14: 1420 | D14: 0 | E14: 1420 | F14: =+E14-(E14*3.99/100) -> 1363.342 | G14: =SUM(D14-B14) -> -1650 | H14: =SUM(E14-C14) -> 0 | I14: =+C14*2/12 -> 236.66667 | J14: 200 | K14: 0 | L14: =+E14+B14 -> 3070 | M14: =SUM(B14-J14) -> 1450 | N14: =SUM(E14-K14) -> 1420
A15: =+A14+1 -> 46247 | B15: 2385 | C15: 4310 | D15: 0 | E15: 4310 | F15: =+E15-(E15*3.99/100) -> 4138.031 | G15: =SUM(D15-B15) -> -2385 | H15: =SUM(E15-C15) -> 0 | I15: =+C15*2/12 -> 718.33333 | J15: 130 | K15: 0 | L15: =+E15+B15 -> 6695 | M15: =SUM(B15-J15) -> 2255 | N15: =SUM(E15-K15) -> 4310
A16: =+A15+1 -> 46248 | B16: 2820 | C16: 2750 | D16: 0 | E16: 2750 | F16: =+E16-(E16*3.99/100) -> 2640.275 | G16: =SUM(D16-B16) -> -2820 | H16: =SUM(E16-C16) -> 0 | I16: =+C16*2/12 -> 458.33333 | J16: 0 | K16: 830 | L16: =+E16+B16 -> 5570 | M16: =SUM(B16-J16) -> 2820 | N16: =SUM(E16-K16) -> 1920
A17: =+A16+1 -> 46249 | B17: 820 | C17: 2900 | D17: 0 | E17: 2900 | F17: =+E17-(E17*3.99/100) -> 2784.29 | G17: =SUM(D17-B17) -> -820 | H17: =SUM(E17-C17) -> 0 | I17: =+C17*2/12 -> 483.33333 | J17: 10100 | K17: 17650 | L17: =+E17+B17 -> 3720 | M17: =SUM(B17-J17) -> -9280 | N17: =SUM(E17-K17) -> -14750
A18: =+A17+1 -> 46250 | B18: 720 | C18: 2250 | D18: 0 | E18: 2250 | F18: =+E18-(E18*3.99/100) -> 2160.225 | G18: =SUM(D18-B18) -> -720 | H18: =SUM(E18-C18) -> 0 | I18: =+C18*2/12 -> 375 | J18: 0 | K18: 0 | L18: =+E18+B18 -> 2970 | M18: =SUM(B18-J18) -> 720 | N18: =SUM(E18-K18) -> 2250
A19: =+A18+1 -> 46251 | B19: 850 | C19: 1660 | D19: 0 | E19: 1660 | F19: =+E19-(E19*3.99/100) -> 1593.766 | G19: =SUM(D19-B19) -> -850 | H19: =SUM(E19-C19) -> 0 | I19: =+C19*2/12 -> 276.66667 | J19: 470 | K19: 0 | L19: =+E19+B19 -> 2510 | M19: =SUM(B19-J19) -> 380 | N19: =SUM(E19-K19) -> 1660
A20: =+A19+1 -> 46252 | B20: 400 | C20: 2300 | D20: 0 | E20: 2300 | F20: =+E20-(E20*3.99/100) -> 2208.23 | G20: =SUM(D20-B20) -> -400 | H20: =SUM(E20-C20) -> 0 | I20: =+C20*2/12 -> 383.33333 | J20: 125 | K20: 0 | L20: =+E20+B20 -> 2700 | M20: =SUM(B20-J20) -> 275 | N20: =SUM(E20-K20) -> 2300
A21: =+A20+1 -> 46253 | B21: 2450 | C21: 1970 | D21: 0 | E21: 1970 | F21: =+E21-(E21*3.99/100) -> 1891.397 | G21: =SUM(D21-B21) -> -2450 | H21: =SUM(E21-C21) -> 0 | I21: =+C21*2/12 -> 328.33333 | J21: 200 | K21: 1050 | L21: =+E21+B21 -> 4420 | M21: =SUM(B21-J21) -> 2250 | N21: =SUM(E21-K21) -> 920 | R21: 5
A22: =+A21+1 -> 46254 | B22: 750 | C22: 6250 | D22: 0 | E22: 6250 | F22: =+E22-(E22*3.99/100) -> 6000.625 | G22: =SUM(D22-B22) -> -750 | H22: =SUM(E22-C22) -> 0 | I22: =+C22*2/12 -> 1041.6667 | J22: 1700 | K22: 4810 | L22: =+E22+B22 -> 7000 | M22: =SUM(B22-J22) -> -950 | N22: =SUM(E22-K22) -> 1440
A23: =+A22+1 -> 46255 | B23: 0 | C23: 2815 | D23: 0 | E23: 2815 | F23: =+E23-(E23*3.99/100) -> 2702.6815 | G23: =SUM(D23-B23) -> 0 | H23: =SUM(E23-C23) -> 0 | I23: =+C23*2/12 -> 469.16667 | J23: 100 | K23: 0 | L23: =+E23+B23 -> 2815 | M23: =SUM(B23-J23) -> -100 | N23: =SUM(E23-K23) -> 2815
A24: =+A23+1 -> 46256 | B24: 3145 | C24: 10090 | D24: 0 | E24: 10090 | F24: =+E24-(E24*3.99/100) -> 9687.409 | G24: =SUM(D24-B24) -> -3145 | H24: =SUM(E24-C24) -> 0 | I24: =+C24*2/12 -> 1681.6667 | J24: 0 | K24: 0 | L24: =+E24+B24 -> 13235 | M24: =SUM(B24-J24) -> 3145 | N24: =SUM(E24-K24) -> 10090
A25: =+A24+1 -> 46257 | B25: 1550 | C25: 0 | D25: 0 | E25: 0 | F25: =+E25-(E25*3.99/100) -> 0 | G25: =SUM(D25-B25) -> -1550 | H25: =SUM(E25-C25) -> 0 | I25: =+C25*2/12 -> 0 | J25: 0 | K25: 115 | L25: =+E25+B25 -> 1550 | M25: =SUM(B25-J25) -> 1550 | N25: =SUM(E25-K25) -> -115
A26: =+A25+1 -> 46258 | B26: 100 | C26: 6040 | D26: 0 | E26: 6040 | F26: =+E26-(E26*3.99/100) -> 5799.004 | G26: =SUM(D26-B26) -> -100 | H26: =SUM(E26-C26) -> 0 | I26: =+C26*2/12 -> 1006.6667 | J26: 550 | K26: 3200 | L26: =+E26+B26 -> 6140 | M26: =SUM(B26-J26) -> -450 | N26: =SUM(E26-K26) -> 2840
A27: =+A26+1 -> 46259 | B27: 0 | C27: 840 | D27: 0 | E27: 840 | F27: =+E27-(E27*3.99/100) -> 806.484 | G27: =SUM(D27-B27) -> 0 | H27: =SUM(E27-C27) -> 0 | I27: =+C27*2/12 -> 140 | J27: 0 | K27: 0 | L27: =+E27+B27 -> 840 | M27: =SUM(B27-J27) -> 0 | N27: =SUM(E27-K27) -> 840
A28: =+A27+1 -> 46260 | B28: 400 | C28: 3890 | D28: 0 | E28: 3890 | F28: =+E28-(E28*3.99/100) -> 3734.789 | G28: =SUM(D28-B28) -> -400 | H28: =SUM(E28-C28) -> 0 | I28: =+C28*2/12 -> 648.33333 | J28: 1700 | K28: 0 | L28: =+E28+B28 -> 4290 | M28: =SUM(B28-J28) -> -1300 | N28: =SUM(E28-K28) -> 3890
A29: =+A28+1 -> 46261 | B29: 850 | C29: 4340 | D29: 0 | E29: 4340 | F29: =+E29-(E29*3.99/100) -> 4166.834 | G29: =SUM(D29-B29) -> -850 | H29: =SUM(E29-C29) -> 0 | I29: =+C29*2/12 -> 723.33333 | J29: 580 | K29: 0 | L29: =+E29+B29 -> 5190 | M29: =SUM(B29-J29) -> 270 | N29: =SUM(E29-K29) -> 4340
A30: =+A29+1 -> 46262 | B30: 1530 | C30: 2890 | D30: 0 | E30: 2890 | F30: =+E30-(E30*3.99/100) -> 2774.689 | G30: =SUM(D30-B30) -> -1530 | H30: =SUM(E30-C30) -> 0 | I30: =+C30*2/12 -> 481.66667 | J30: 100 | K30: 31365 | L30: =+E30+B30 -> 4420 | M30: =SUM(B30-J30) -> 1430 | N30: =SUM(E30-K30) -> -28475
A31: =+A30+1 -> 46263 | B31: 4300 | C31: 4550 | D31: 0 | E31: 4500 | F31: =+E31-(E31*3.99/100) -> 4320.45 | G31: =SUM(D31-B31) -> -4300 | H31: =SUM(E31-C31) -> -50 | I31: =+C31*2/12 -> 758.33333 | J31: 390 | K31: 0 | L31: =+E31+B31 -> 8800 | M31: =SUM(B31-J31) -> 3910 | N31: =SUM(E31-K31) -> 4500
A32: =+A31+1 -> 46264 | B32: 0 | C32: 2540 | D32: 0 | E32: 2540 | F32: =+E32-(E32*3.99/100) -> 2438.654 | G32: =SUM(D32-B32) -> 0 | H32: =SUM(E32-C32) -> 0 | I32: =+C32*2/12 -> 423.33333 | J32: 795 | K32: 0 | L32: =+E32+B32 -> 2540 | M32: =SUM(B32-J32) -> -795 | N32: =SUM(E32-K32) -> 2540
A33: 31 Temmuz 2026 Cuma | B33: 800 | C33: 4000 | D33: 0 | E33: 4000 | F33: =+E33-(E33*3.99/100) -> 3840.4 | G33: =SUM(D33-B33) -> -800 | H33: =SUM(E33-C33) -> 0 | I33: =+C33*2/12 -> 666.66667 | J33: 700 | K33: 0 | L33: =+E33+B33 -> 4800 | M33: =SUM(B33-J33) -> 100 | N33: =SUM(E33-K33) -> 4000
A34: TOPLAM | B34: =SUM(B3:B33) -> 37020 | C34: =SUM(C3:C33) -> 96585 | D34: =SUM(D3:D33) -> 0 | E34: =SUM(E3:E33) -> 96535 | F34: =+E34-(E34*3.99/100) -> 92683.254 | G34: =SUM(G3:G33) -> -37020 | H34: =SUM(H3:H32) -> -50 | I34: =SUM(I3:I33) -> 16097.5 | J34: =SUM(J3:J33) -> 30255 | L34: =SUM(L3:L32) -> 128755 | M34: =SUM(M3:M32) -> 5070 | N34: =SUM(N3:N32) -> 5095
E35: KESİNTİ | F35: =+E34-F34 -> 3851.7465 | L35: =AVERAGE(L3:L32) -> 4291.8333
H37: TOPLAM CİRO | J37: =SUM(L3:L32) -> 128755
H38: TOPLAM HARCAMA | J38: =SUM(+J34+K34) -> 30255
H39: TOPLAM CİRODAN KALAN | J39: =SUM(M34+N34) -> 10165

Sheet TEMMUZ 2026
A2: SATIŞ | B2: NAKİT SATIŞ | C2: KREDİ SATIŞ | D2: Z RAPORU NAKİT | E2: Z RAPORU KREDİ | F2: YATACAK OLAN | G2: NAKİT FARK | H2: KREDİ FARK | I2: KDV | J2: NAKİT HARCAMA | K2: KREDİ HARCAMA | L2: CİRO | M2: CEP NAKİT | N2: CEP KREDİ
A3: 46204 | B3: 500 | C3: 5340 | D3: 0 | E3: 5340 | F3: =+E3-(E3*3.99/100) -> 5126.934 | G3: =SUM(D3-B3) -> -500 | H3: =SUM(E3-C3) -> 0 | I3: 915 | J3: 0 | K3: 0 | L3: =+E3+B3 -> 5840 | M3: =SUM(B3-J3) -> 500 | N3: =SUM(E3-K3) -> 5340
A4: =+A3+1 -> 46205 | B4: 200 | C4: 7760 | D4: 0 | E4: 7760 | F4: =+E4-(E4*3.99/100) -> 7450.376 | G4: =SUM(D4-B4) -> -200 | H4: =SUM(E4-C4) -> 0 | I4: 1153.34 | J4: 0 | K4: 330 | L4: =+E4+B4 -> 7960 | M4: =SUM(B4-J4) -> 200 | N4: =SUM(E4-K4) -> 7430
A5: =+A4+1 -> 46206 | B5: 600 | C5: 2340 | D5: 0 | E5: 2340 | F5: =+E5-(E5*3.99/100) -> 2246.634 | G5: =SUM(D5-B5) -> -600 | H5: =SUM(E5-C5) -> 0 | I5: 391.68 | J5: 200 | K5: 0 | L5: =+E5+B5 -> 2940 | M5: =SUM(B5-J5) -> 400 | N5: =SUM(E5-K5) -> 2340
A6: =+A5+1 -> 46207 | B6: 1400 | C6: 4400 | D6: 0 | E6: 4400 | F6: =+E6-(E6*3.99/100) -> 4224.44 | G6: =SUM(D6-B6) -> -1400 | H6: =SUM(E6-C6) -> 0 | I6: 778.34 | J6: 0 | K6: 190 | L6: =+E6+B6 -> 5800 | M6: =SUM(B6-J6) -> 1400 | N6: =SUM(E6-K6) -> 4210
A7: =+A6+1 -> 46208 | B7: 4020 | C7: 1640 | D7: 0 | E7: 1640 | F7: =+E7-(E7*3.99/100) -> 1574.564 | G7: =SUM(D7-B7) -> -4020 | H7: =SUM(E7-C7) -> 0 | I7: 298.33 | J7: 750 | K7: 1510 | L7: =+E7+B7 -> 5660 | M7: =SUM(B7-J7) -> 3270 | N7: =SUM(E7-K7) -> 130
A8: =+A7+1 -> 46209 | B8: 500 | C8: 8740 | D8: 0 | E8: 8740 | F8: =+E8-(E8*3.99/100) -> 8391.274 | G8: =SUM(D8-B8) -> -500 | H8: =SUM(E8-C8) -> 0 | I8: 1390.01 | J8: 0 | K8: 0 | L8: =+E8+B8 -> 9240 | M8: 0 | N8: =SUM(E8-K8) -> 8740
A9: =+A8+1 -> 46210 | B9: 720 | C9: 2720 | D9: 0 | E9: 2720 | F9: =+E9-(E9*3.99/100) -> 2611.472 | G9: =SUM(D9-B9) -> -720 | H9: =SUM(E9-C9) -> 0 | I9: 453.33 | J9: 3225 | K9: 0 | L9: =+E9+B9 -> 3440 | M9: =SUM(B9-J9) -> -2505 | N9: =SUM(E9-K9) -> 2720
A10: =+A9+1 -> 46211 | B10: 500 | C10: 4520 | D10: 0 | E10: 4520 | F10: =+E10-(E10*3.99/100) -> 4339.652 | G10: =SUM(D10-B10) -> -500 | H10: =SUM(E10-C10) -> 0 | I10: 753.34 | J10: 7500 | K10: 41400 | L10: =+E10+B10 -> 5020 | M10: =SUM(B10-J10) -> -7000 | N10: =SUM(E10-K10) -> -36880
A11: =+A10+1 -> 46212 | B11: 680 | C11: 4300 | D11: 0 | E11: 4300 | F11: =+E11-(E11*3.99/100) -> 4128.43 | G11: =SUM(D11-B11) -> -680 | H11: =SUM(E11-C11) -> 0 | I11: 716.67 | J11: 215 | K11: 0 | L11: =+E11+B11 -> 4980 | M11: =SUM(B11-J11) -> 465 | N11: =SUM(E11-K11) -> 4300
A12: =+A11+1 -> 46213 | B12: 0 | C12: 3645 | D12: 0 | E12: 3645 | F12: =+E12-(E12*3.99/100) -> 3499.5645 | G12: =SUM(D12-B12) -> 0 | H12: =SUM(E12-C12) -> 0 | I12: 607.51 | J12: 0 | K12: 85 | L12: =+E12+B12 -> 3645 | M12: =SUM(B12-J12) -> 0 | N12: =SUM(E12-K12) -> 3560
A13: =+A12+1 -> 46214 | B13: 200 | C13: 4270 | D13: 0 | E13: 4270 | F13: =+E13-(E13*3.99/100) -> 4099.627 | G13: =SUM(D13-B13) -> -200 | H13: =SUM(E13-C13) -> 0 | I13: 711.67 | J13: 1000 | K13: 377 | L13: =+E13+B13 -> 4470 | M13: =SUM(B13-J13) -> -800 | N13: =SUM(E13-K13) -> 3893
A14: =+A13+1 -> 46215 | B14: 370 | C14: 3400 | D14: 0 | E14: 3400 | F14: =+E14-(E14*3.99/100) -> 3264.34 | G14: =SUM(D14-B14) -> -370 | H14: =SUM(E14-C14) -> 0 | I14: 566.67 | J14: 0 | K14: 0 | L14: =+E14+B14 -> 3770 | M14: =SUM(B14-J14) -> 370 | N14: =SUM(E14-K14) -> 3400
A15: =+A14+1 -> 46216 | B15: 2400 | C15: 6330 | D15: 0 | E15: 6330 | F15: =+E15-(E15*3.99/100) -> 6077.433 | G15: =SUM(D15-B15) -> -2400 | H15: =SUM(E15-C15) -> 0 | I15: 1113.33 | J15: 0 | K15: 620 | L15: =+E15+B15 -> 8730 | M15: =SUM(B15-J15) -> 2400 | N15: =SUM(E15-K15) -> 5710
A16: =+A15+1 -> 46217 | B16: 400 | C16: 900 | D16: 0 | E16: 900 | F16: =+E16-(E16*3.99/100) -> 864.09 | G16: =SUM(D16-B16) -> -400 | H16: =SUM(E16-C16) -> 0 | I16: 150 | J16: 350 | K16: 0 | L16: =+E16+B16 -> 1300 | M16: =SUM(B16-J16) -> 50 | N16: =SUM(E16-K16) -> 900
A17: =+A16+1 -> 46218 | B17: 2800 | C17: 2120 | D17: 0 | E17: 2120 | F17: =+E17-(E17*3.99/100) -> 2035.412 | G17: =SUM(D17-B17) -> -2800 | H17: =SUM(E17-C17) -> 0 | I17: 353.33 | J17: 0 | K17: 0 | L17: =+E17+B17 -> 4920 | M17: =SUM(B17-J17) -> 2800 | N17: =SUM(E17-K17) -> 2120
A18: =+A17+1 -> 46219 | B18: 2250 | C18: 6020 | D18: 0 | E18: 6020 | F18: =+E18-(E18*3.99/100) -> 5779.802 | G18: =SUM(D18-B18) -> -2250 | H18: =SUM(E18-C18) -> 0 | I18: 978.32 | J18: 0 | K18: 0 | L18: =+E18+B18 -> 8270 | M18: =SUM(B18-J18) -> 2250 | N18: =SUM(E18-K18) -> 6020
A19: =+A18+1 -> 46220 | B19: 1500 | C19: 3010 | D19: 0 | E19: 3010 | F19: =+E19-(E19*3.99/100) -> 2889.901 | G19: =SUM(D19-B19) -> -1500 | H19: =SUM(E19-C19) -> 0 | I19: 501.68 | J19: 510 | K19: 0 | L19: =+E19+B19 -> 4510 | M19: =SUM(B19-J19) -> 990 | N19: =SUM(E19-K19) -> 3010
A20: =+A19+1 -> 46221 | B20: 240 | C20: 4510 | D20: 0 | E20: 4510 | F20: =+E20-(E20*3.99/100) -> 4330.051 | G20: =SUM(D20-B20) -> -240 | H20: =SUM(E20-C20) -> 0 | I20: 751.66 | J20: 8300 | K20: 36200 | L20: =+E20+B20 -> 4750 | M20: =SUM(B20-J20) -> -8060 | N20: =SUM(E20-K20) -> -31690
A21: =+A20+1 -> 46222 | B21: 0 | C21: 700 | D21: 0 | E21: 700 | F21: =+E21-(E21*3.99/100) -> 672.07 | G21: =SUM(D21-B21) -> 0 | H21: =SUM(E21-C21) -> 0 | I21: 116.66 | J21: 0 | K21: 0 | L21: =+E21+B21 -> 700 | M21: =SUM(B21-J21) -> 0 | N21: =SUM(E21-K21) -> 700 | R21: 5
A22: =+A21+1 -> 46223 | B22: 900 | C22: 870 | D22: 0 | E22: 870 | F22: =+E22-(E22*3.99/100) -> 835.287 | G22: =SUM(D22-B22) -> -900 | H22: =SUM(E22-C22) -> 0 | I22: 145 | J22: 200 | K22: 3200 | L22: =+E22+B22 -> 1770 | M22: =SUM(B22-J22) -> 700 | N22: =SUM(E22-K22) -> -2330
A23: =+A22+1 -> 46224 | B23: 900 | C23: 2950 | D23: 0 | E23: 2950 | F23: =+E23-(E23*3.99/100) -> 2832.295 | G23: =SUM(D23-B23) -> -900 | H23: =SUM(E23-C23) -> 0 | I23: 481.66 | J23: 300 | K23: 2140 | L23: =+E23+B23 -> 3850 | M23: =SUM(B23-J23) -> 600 | N23: =SUM(E23-K23) -> 810
A24: =+A23+1 -> 46225 | B24: 200 | C24: 3680 | D24: 0 | E24: 3680 | F24: =+E24-(E24*3.99/100) -> 3533.168 | G24: =SUM(D24-B24) -> -200 | H24: =SUM(E24-C24) -> 0 | I24: 613.33 | J24: 120 | K24: 0 | L24: =+E24+B24 -> 3880 | M24: =SUM(B24-J24) -> 80 | N24: =SUM(E24-K24) -> 3680
A25: =+A24+1 -> 46226 | B25: 950 | C25: 6240 | D25: 0 | E25: 6240 | F25: =+E25-(E25*3.99/100) -> 5991.024 | G25: =SUM(D25-B25) -> -950 | H25: =SUM(E25-C25) -> 0 | I25: 1040 | J25: 350 | K25: 0 | L25: =+E25+B25 -> 7190 | M25: =SUM(B25-J25) -> 600 | N25: =SUM(E25-K25) -> 6240
A26: =+A25+1 -> 46227 | B26: 2400 | C26: 3220 | D26: 0 | E26: 3220 | F26: =+E26-(E26*3.99/100) -> 3091.522 | G26: =SUM(D26-B26) -> -2400 | H26: =SUM(E26-C26) -> 0 | I26: 511.67 | J26: 0 | K26: 2970 | L26: =+E26+B26 -> 5620 | M26: =SUM(B26-J26) -> 2400 | N26: =SUM(E26-K26) -> 250
A27: =+A26+1 -> 46228 | B27: 1890 | C27: 3550 | D27: 0 | E27: 3550 | F27: =+E27-(E27*3.99/100) -> 3408.355 | G27: =SUM(D27-B27) -> -1890 | H27: =SUM(E27-C27) -> 0 | I27: 591.67 | J27: 315 | K27: 0 | L27: =+E27+B27 -> 5440 | M27: =SUM(B27-J27) -> 1575 | N27: =SUM(E27-K27) -> 3550
A28: =+A27+1 -> 46229 | B28: 0 | C28: 530 | D28: 0 | E28: 530 | F28: =+E28-(E28*3.99/100) -> 508.853 | G28: =SUM(D28-B28) -> 0 | H28: =SUM(E28-C28) -> 0 | I28: 88.33 | J28: 1395 | K28: 0 | L28: =+E28+B28 -> 530 | M28: =SUM(B28-J28) -> -1395 | N28: =SUM(E28-K28) -> 530
A29: =+A28+1 -> 46230 | B29: 1300 | C29: 2500 | D29: 0 | E29: 2500 | F29: =+E29-(E29*3.99/100) -> 2400.25 | G29: =SUM(D29-B29) -> -1300 | H29: =SUM(E29-C29) -> 0 | I29: 416.66 | J29: 3720 | K29: 18400 | L29: =+E29+B29 -> 3800 | M29: =SUM(B29-J29) -> -2420 | N29: =SUM(E29-K29) -> -15900
A30: =+A29+1 -> 46231 | B30: 1715 | C30: 4530 | D30: 0 | E30: 4530 | F30: =+E30-(E30*3.99/100) -> 4349.253 | G30: =SUM(D30-B30) -> -1715 | H30: =SUM(E30-C30) -> 0 | I30: 688.34 | J30: 200 | K30: 0 | L30: =+E30+B30 -> 6245 | M30: =SUM(B30-J30) -> 1515 | N30: =SUM(E30-K30) -> 4530
A31: =+A30+1 -> 46232 | B31: 760 | C31: 6510 | D31: 0 | E31: 6510 | F31: =+E31-(E31*3.99/100) -> 6250.251 | G31: =SUM(D31-B31) -> -760 | H31: =SUM(E31-C31) -> 0 | I31: 1110 | J31: 0 | K31: 7000 | L31: =+E31+B31 -> 7270 | M31: =SUM(B31-J31) -> 760 | N31: =SUM(E31-K31) -> -490
A32: =+A31+1 -> 46233 | B32: 1200 | C32: 1950 | D32: 0 | E32: 1950 | F32: =+E32-(E32*3.99/100) -> 1872.195 | G32: =SUM(D32-B32) -> -1200 | H32: =SUM(E32-C32) -> 0 | I32: 325.01 | J32: 0 | K32: 0 | L32: =+E32+B32 -> 3150 | M32: =SUM(B32-J32) -> 1200 | N32: =SUM(E32-K32) -> 1950
A33: 31 Temmuz 2026 Cuma | B33: 1000 | C33: 5150 | D33: 0 | E33: 5150 | F33: =+E33-(E33*3.99/100) -> 4944.515 | G33: =SUM(D33-B33) -> -1000 | H33: =SUM(E33-C33) -> 0 | I33: 625 | J33: 50 | K33: 60 | L33: =+E33+B33 -> 6150 | M33: =SUM(B33-J33) -> 950 | N33: =SUM(E33-K33) -> 5090
A34: TOPLAM | B34: =SUM(B3:B33) -> 32495 | C34: =SUM(C3:C33) -> 118345 | D34: =SUM(D3:D33) -> 0 | E34: =SUM(E3:E33) -> 118345 | F34: =+E34-(E34*3.99/100) -> 113623.03 | G34: =SUM(G3:G32) -> -31495 | H34: =SUM(H3:H32) -> 0 | I34: =SUM(I3:I33) -> 19337.54 | J34: =SUM(J3:J33) -> 28700 | K34: =SUM(K3:K33) -> 114482 | L34: =SUM(L3:L32) -> 144690 | M34: =SUM(M3:M32) -> 2345 | N34: =SUM(N3:N32) -> -1227
E35: KESİNTİ | F35: =+E34-F34 -> 4721.9655 | L35: =AVERAGE(L3:L32) -> 4823
H37: TOPLAM CİRO | J37: =SUM(L3:L32) -> 144690
H38: TOPLAM HARCAMA | J38: =SUM(+J34+K34) -> 143182
H39: TOPLAM CİRODAN KALAN | J39: =SUM(M34+N34) -> 1118

Sheet HAZİRAN 2026
A2: SATIŞ | B2: NAKİT SATIŞ | C2: KREDİ SATIŞ | D2: Z RAPORU NAKİT | E2: Z RAPORU KREDİ | F2: YATACAK OLAN | G2: NAKİT FARK | H2: KREDİ FARK | I2: KDV | J2: NAKİT HARCAMA | K2: KREDİ HARCAMA | L2: CİRO | M2: CEP NAKİT | N2: CEP KREDİ
A3: 46174 | B3: 700 | C3: =400+2050 -> 2450 | D3: 0 | E3: 2050 | F3: =+E3-(E3*3.99/100) -> 1968.205 | G3: =SUM(D3-B3) -> -700 | H3: =SUM(E3-C3) -> -400 | I3: 341.66 | J3: 350 | K3: 0 | L3: =+E3+B3 -> 2750 | M3: =SUM(B3-J3) -> 350 | N3: =SUM(E3-K3) -> 2050
A4: =+A3+1 -> 46175 | B4: 2370 | C4: =5440+1650 -> 7090 | D4: 0 | E4: =1650+5440 -> 7090 | F4: =+E4-(E4*3.99/100) -> 6807.109 | G4: =SUM(D4-B4) -> -2370 | H4: =SUM(E4-C4) -> 0 | I4: =631.67+275 -> 906.67 | J4: 0 | K4: 0 | L4: =+E4+B4 -> 9460 | M4: =SUM(B4-J4) -> 2370 | N4: =SUM(E4-K4) -> 7090
A5: =+A4+1 -> 46176 | B5: 745 | C5: 1300 | D5: 0 | E5: 1300 | F5: =+E5-(E5*3.99/100) -> 1248.13 | G5: =SUM(D5-B5) -> -745 | H5: =SUM(E5-C5) -> 0 | I5: 216.67 | J5: 0 | K5: 0 | L5: =+E5+B5 -> 2045 | M5: =SUM(B5-J5) -> 745 | N5: =SUM(E5-K5) -> 1300
A6: =+A5+1 -> 46177 | B6: 500 | C6: 1900 | D6: 0 | E6: 1900 | F6: =+E6-(E6*3.99/100) -> 1824.19 | G6: =SUM(D6-B6) -> -500 | H6: =SUM(E6-C6) -> 0 | I6: 316.66 | J6: 145 | K6: 0 | L6: =+E6+B6 -> 2400 | M6: =SUM(B6-J6) -> 355 | N6: =SUM(E6-K6) -> 1900
A7: =+A6+1 -> 46178 | B7: 2400 | C7: 7440 | D7: 275 | E7: =7190+250 -> 7440 | F7: =+E7-(E7*3.99/100) -> 7143.144 | G7: =SUM(D7-B7) -> -2125 | H7: =SUM(E7-C7) -> 0 | I7: 1285.82 | J7: 0 | K7: 1505 | L7: =+E7+B7 -> 9840 | M7: =SUM(B7-J7) -> 2400 | N7: =SUM(E7-K7) -> 5935
A8: =+A7+1 -> 46179 | B8: 650 | C8: 6070 | D8: 0 | E8: 6070 | F8: =+E8-(E8*3.99/100) -> 5827.807 | G8: =SUM(D8-B8) -> -650 | H8: =SUM(E8-C8) -> 0 | I8: 1011.67 | J8: 3450 | K8: 0 | L8: =+E8+B8 -> 6720 | M8: 0 | N8: =SUM(E8-K8) -> 6070
A9: =+A8+1 -> 46180 | B9: 0 | C9: 360 | D9: 0 | E9: 360 | F9: =+E9-(E9*3.99/100) -> 345.636 | G9: =SUM(D9-B9) -> 0 | H9: =SUM(E9-C9) -> 0 | I9: 60 | J9: 0 | K9: 0 | L9: =+E9+B9 -> 360 | M9: =SUM(B9-J9) -> 0 | N9: =SUM(E9-K9) -> 360
A10: =+A9+1 -> 46181 | B10: 1800 | C10: 550 | D10: 0 | E10: 550 | F10: =+E10-(E10*3.99/100) -> 528.055 | G10: =SUM(D10-B10) -> -1800 | H10: =SUM(E10-C10) -> 0 | I10: 91.67 | J10: 0 | K10: 0 | L10: =+E10+B10 -> 2350 | M10: =SUM(B10-J10) -> 1800 | N10: =SUM(E10-K10) -> 550
A11: =+A10+1 -> 46182 | B11: 750 | C11: 3450 | D11: 0 | E11: 3450 | F11: =+E11-(E11*3.99/100) -> 3312.345 | G11: =SUM(D11-B11) -> -750 | H11: =SUM(E11-C11) -> 0 | I11: 574.99 | J11: 10100 | K11: 33860 | L11: =+E11+B11 -> 4200 | M11: =SUM(B11-J11) -> -9350 | N11: =SUM(E11-K11) -> -30410
A12: =+A11+1 -> 46183 | B12: 3820 | C12: 6790 | D12: 0 | E12: 6790 | F12: =+E12-(E12*3.99/100) -> 6519.079 | G12: =SUM(D12-B12) -> -3820 | H12: =SUM(E12-C12) -> 0 | I12: 1131.66 | J12: 350 | K12: 1700 | L12: =+E12+B12 -> 10610 | M12: =SUM(B12-J12) -> 3470 | N12: =SUM(E12-K12) -> 5090
A13: =+A12+1 -> 46184 | B13: 3470 | C13: =350+4100 -> 4450 | D13: 370 | E13: 4100 | F13: =+E13-(E13*3.99/100) -> 3936.41 | G13: =SUM(D13-B13) -> -3100 | H13: =SUM(E13-C13) -> -350 | I13: 745.01 | J13: 0 | K13: 0 | L13: =+E13+B13 -> 7570 | M13: =SUM(B13-J13) -> 3470 | N13: =SUM(E13-K13) -> 4100
A14: =+A13+1 -> 46185 | B14: 1490 | C14: =2950+920 -> 3870 | D14: 0 | E14: 920 | F14: =+E14-(E14*3.99/100) -> 883.292 | G14: =SUM(D14-B14) -> -1490 | H14: =SUM(E14-C14) -> -2950 | I14: 153.33 | J14: 70 | K14: 0 | L14: =+E14+B14 -> 2410 | M14: =SUM(B14-J14) -> 1420 | N14: =SUM(E14-K14) -> 920
A15: =+A14+1 -> 46186 | B15: 750 | C15: 3640 | D15: 0 | E15: 3640 | F15: =+E15-(E15*3.99/100) -> 3494.764 | G15: =SUM(D15-B15) -> -750 | H15: =SUM(E15-C15) -> 0 | I15: 620 | J15: 0 | K15: 550 | L15: =+E15+B15 -> 4390 | M15: =SUM(B15-J15) -> 750 | N15: =SUM(E15-K15) -> 3090
A16: =+A15+1 -> 46187 | B16: 600 | C16: 1220 | D16: 0 | E16: 1220 | F16: =+E16-(E16*3.99/100) -> 1171.322 | G16: =SUM(D16-B16) -> -600 | H16: =SUM(E16-C16) -> 0 | I16: 203.34 | J16: 200 | K16: 0 | L16: =+E16+B16 -> 1820 | M16: =SUM(B16-J16) -> 400 | N16: =SUM(E16-K16) -> 1220
A17: =+A16+1 -> 46188 | B17: 1200 | C17: 2330 | D17: 0 | E17: 2330 | F17: =+E17-(E17*3.99/100) -> 2237.033 | G17: =SUM(D17-B17) -> -1200 | H17: =SUM(E17-C17) -> 0 | I17: 401.66 | J17: 7350 | K17: 20995 | L17: =+E17+B17 -> 3530 | M17: =SUM(B17-J17) -> -6150 | N17: =SUM(E17-K17) -> -18665
A18: =+A17+1 -> 46189 | B18: 100 | C18: 1850 | D18: 0 | E18: 1850 | F18: =+E18-(E18*3.99/100) -> 1776.185 | G18: =SUM(D18-B18) -> -100 | H18: =SUM(E18-C18) -> 0 | I18: 283.33 | J18: 135 | K18: 0 | L18: =+E18+B18 -> 1950 | M18: =SUM(B18-J18) -> -35 | N18: =SUM(E18-K18) -> 1850
A19: =+A18+1 -> 46190 | B19: 1300 | C19: 3630 | D19: 0 | E19: 3630 | F19: =+E19-(E19*3.99/100) -> 3485.163 | G19: =SUM(D19-B19) -> -1300 | H19: =SUM(E19-C19) -> 0 | I19: 604.99 | J19: 100 | K19: 0 | L19: =+E19+B19 -> 4930 | M19: =SUM(B19-J19) -> 1200 | N19: =SUM(E19-K19) -> 3630
A20: =+A19+1 -> 46191 | B20: 160 | C20: 3270 | D20: 0 | E20: 3270 | F20: =+E20-(E20*3.99/100) -> 3139.527 | G20: =SUM(D20-B20) -> -160 | H20: =SUM(E20-C20) -> 0 | I20: 545.01 | J20: 3500 | K20: 7755 | L20: =+E20+B20 -> 3430 | M20: =SUM(B20-J20) -> -3340 | N20: =SUM(E20-K20) -> -4485
A21: =+A20+1 -> 46192 | B21: 2500 | C21: 2940 | D21: 0 | E21: 2940 | F21: =+E21-(E21*3.99/100) -> 2822.694 | G21: =SUM(D21-B21) -> -2500 | H21: =SUM(E21-C21) -> 0 | I21: 520 | J21: 0 | K21: 970 | L21: =+E21+B21 -> 5440 | M21: =SUM(B21-J21) -> 2500 | N21: =SUM(E21-K21) -> 1970 | R21: 5
A22: =+A21+1 -> 46193 | B22: 600 | C22: 6470 | D22: 0 | E22: 6470 | F22: =+E22-(E22*3.99/100) -> 6211.847 | G22: =SUM(D22-B22) -> -600 | H22: =SUM(E22-C22) -> 0 | I22: 978.34 | J22: 950 | K22: 4900 | L22: =+E22+B22 -> 7070 | M22: =SUM(B22-J22) -> -350 | N22: =SUM(E22-K22) -> 1570
A23: =+A22+1 -> 46194 | B23: 500 | C23: 4240 | D23: 0 | E23: 4240 | F23: =+E23-(E23*3.99/100) -> 4070.824 | G23: =SUM(D23-B23) -> -500 | H23: =SUM(E23-C23) -> 0 | I23: 706.67 | J23: 0 | K23: 0 | L23: =+E23+B23 -> 4740 | M23: =SUM(B23-J23) -> 500 | N23: =SUM(E23-K23) -> 4240
A24: =+A23+1 -> 46195 | B24: 890 | C24: 2520 | D24: 0 | E24: 2520 | F24: =+E24-(E24*3.99/100) -> 2419.452 | G24: =SUM(D24-B24) -> -890 | H24: =SUM(E24-C24) -> 0 | I24: 420 | J24: 2300 | K24: 10690 | L24: =+E24+B24 -> 3410 | M24: =SUM(B24-J24) -> -1410 | N24: =SUM(E24-K24) -> -8170
A25: =+A24+1 -> 46196 | B25: 700 | C25: 1600 | D25: 0 | E25: 1600 | F25: =+E25-(E25*3.99/100) -> 1536.16 | G25: =SUM(D25-B25) -> -700 | H25: =SUM(E25-C25) -> 0 | I25: 266.66 | J25: 400 | K25: 920 | L25: =+E25+B25 -> 2300 | M25: =SUM(B25-J25) -> 300 | N25: =SUM(E25-K25) -> 680
A26: =+A25+1 -> 46197 | B26: 0 | C26: 1530 | D26: 0 | E26: 1530 | F26: =+E26-(E26*3.99/100) -> 1468.953 | G26: =SUM(D26-B26) -> 0 | H26: =SUM(E26-C26) -> 0 | I26: 255 | J26: 100 | K26: 0 | L26: =+E26+B26 -> 1530 | M26: =SUM(B26-J26) -> -100 | N26: =SUM(E26-K26) -> 1530
A27: =+A26+1 -> 46198 | B27: 950 | C27: 5845 | D27: 0 | E27: 5845 | F27: =+E27-(E27*3.99/100) -> 5611.7845 | G27: =SUM(D27-B27) -> -950 | H27: =SUM(E27-C27) -> 0 | I27: 999.17 | J27: 0 | K27: 4450 | L27: =+E27+B27 -> 6795 | M27: =SUM(B27-J27) -> 950 | N27: =SUM(E27-K27) -> 1395
A28: =+A27+1 -> 46199 | B28: 2250 | C28: 4140 | D28: 0 | E28: 4140 | F28: =+E28-(E28*3.99/100) -> 3974.814 | G28: =SUM(D28-B28) -> -2250 | H28: =SUM(E28-C28) -> 0 | I28: 690 | J28: 4800 | K28: 5700 | L28: =+E28+B28 -> 6390 | M28: =SUM(B28-J28) -> -2550 | N28: =SUM(E28-K28) -> -1560
A29: =+A28+1 -> 46200 | B29: 2010 | C29: 5930 | D29: 0 | E29: 5930 | F29: =+E29-(E29*3.99/100) -> 5693.393 | G29: =SUM(D29-B29) -> -2010 | H29: =SUM(E29-C29) -> 0 | I29: 1033.33 | J29: 315 | K29: 1050 | L29: =+E29+B29 -> 7940 | M29: =SUM(B29-J29) -> 1695 | N29: =SUM(E29-K29) -> 4880
A30: =+A29+1 -> 46201 | B30: 400 | C30: 450 | D30: 0 | E30: 450 | F30: =+E30-(E30*3.99/100) -> 432.045 | G30: =SUM(D30-B30) -> -400 | H30: =SUM(E30-C30) -> 0 | I30: 0 | J30: 0 | K30: 0 | L30: =+E30+B30 -> 850 | M30: =SUM(B30-J30) -> 400 | N30: =SUM(E30-K30) -> 450
A31: =+A30+1 -> 46202 | B31: 1750 | C31: 2770 | D31: 0 | E31: 2770 | F31: =+E31-(E31*3.99/100) -> 2659.477 | G31: =SUM(D31-B31) -> -1750 | H31: =SUM(E31-C31) -> 0 | I31: 461.66 | J31: 600 | K31: 0 | L31: =+E31+B31 -> 4520 | M31: =SUM(B31-J31) -> 1150 | N31: =SUM(E31-K31) -> 2770
A32: =+A31+1 -> 46203 | B32: 700 | C32: 620 | D32: 0 | E32: 620 | F32: =+E32-(E32*3.99/100) -> 595.262 | G32: =SUM(D32-B32) -> -700 | H32: =SUM(E32-C32) -> 0 | I32: 103.33 | J32: 0 | K32: 0 | L32: =+E32+B32 -> 1320 | M32: =SUM(B32-J32) -> 700 | N32: =SUM(E32-K32) -> 620
F33: =+E33-(E33*3.99/100) -> 0 | G33: =SUM(D33-B33) -> 0 | H33: =SUM(E33-C33) -> 0 | L33: =+E33+B33 -> 0 | M33: =SUM(B33-J33) -> 0 | N33: =SUM(E33-K33) -> 0
A34: TOPLAM | B34: =SUM(B3:B33) -> 36055 | C34: =SUM(C3:C33) -> 100715 | D34: =SUM(D3:D33) -> 645 | E34: =SUM(E3:E33) -> 97015 | F34: =+E34-(E34*3.99/100) -> 93144.102 | G34: =SUM(G3:G32) -> -35410 | H34: =SUM(H3:H32) -> -3700 | I34: =SUM(I3:I33) -> 15928.3 | J34: =SUM(J3:J33) -> 35215 | K34: =SUM(K3:K33) -> 95045 | L34: =SUM(L3:L32) -> 133070 | M34: =SUM(M3:M32) -> 3640 | N34: =SUM(N3:N32) -> 1970
E35: KESİNTİ | F35: =+E34-F34 -> 3870.8985 | L35: =AVERAGE(L3:L32) -> 4435.6667
H37: TOPLAM CİRO | J37: =SUM(L3:L32) -> 133070
H38: TOPLAM HARCAMA | J38: =SUM(+J34+K34) -> 130260
H39: TOPLAM CİRODAN KALAN | J39: =SUM(M34+N34) -> 5610

Sheet MAYIS 2026
A2: SATIŞ | B2: NAKİT SATIŞ | C2: KREDİ SATIŞ | D2: Z RAPORU NAKİT | E2: Z RAPORU KREDİ | F2: YATACAK OLAN | G2: NAKİT FARK | H2: KREDİ FARK | I2: KDV | J2: NAKİT HARCAMA | K2: KREDİ HARCAMA | L2: CİRO | M2: CEP NAKİT | N2: CEP KREDİ
A3: 46143 | B3: 0 | C3: 4650 | D3: 0 | E3: =3260+1390 -> 4650 | F3: =+E3-(E3*3.99/100) -> 4464.465 | G3: =SUM(D3-B3) -> 0 | H3: =SUM(E3-C3) -> 0 | I3: 775 | J3: 350 | K3: 0 | L3: =+E3+B3 -> 4650 | M3: =SUM(B3-J3) -> -350 | N3: =SUM(E3-K3) -> 4650
A4: =+A3+1 -> 46144 | B4: 1920 | C4: 1230 | D4: 0 | E4: 1230 | F4: =+E4-(E4*3.99/100) -> 1180.923 | G4: =SUM(D4-B4) -> -1920 | H4: =SUM(E4-C4) -> 0 | I4: 205 | J4: 0 | K4: 0 | L4: =+E4+B4 -> 3150 | M4: =SUM(B4-J4) -> 1920 | N4: =SUM(E4-K4) -> 1230
A5: =+A4+1 -> 46145 | B5: 0 | C5: 850 | D5: 0 | E5: 850 | F5: =+E5-(E5*3.99/100) -> 816.085 | G5: =SUM(D5-B5) -> 0 | H5: =SUM(E5-C5) -> 0 | I5: 141.67 | J5: 0 | K5: 260 | L5: =+E5+B5 -> 850 | M5: =SUM(B5-J5) -> 0 | N5: =SUM(E5-K5) -> 590
A6: =+A5+1 -> 46146 | B6: 720 | C6: 1660 | D6: 0 | E6: 1660 | F6: =+E6-(E6*3.99/100) -> 1593.766 | G6: =SUM(D6-B6) -> -720 | H6: =SUM(E6-C6) -> 0 | I6: 276.67 | J6: 350 | K6: 0 | L6: =+E6+B6 -> 2380 | M6: =SUM(B6-J6) -> 370 | N6: =SUM(E6-K6) -> 1660
A7: =+A6+1 -> 46147 | B7: 690 | C7: 3930 | D7: 0 | E7: 3930 | F7: =+E7-(E7*3.99/100) -> 3773.193 | G7: =SUM(D7-B7) -> -690 | H7: =SUM(E7-C7) -> 0 | I7: 655.01 | J7: 200 | K7: 1510 | L7: =+E7+B7 -> 4620 | M7: =SUM(B7-J7) -> 490 | N7: =SUM(E7-K7) -> 2420
A8: =+A7+1 -> 46148 | B8: 1800 | C8: 3720 | D8: 0 | E8: 3720 | F8: =+E8-(E8*3.99/100) -> 3571.572 | G8: =SUM(D8-B8) -> -1800 | H8: =SUM(E8-C8) -> 0 | I8: 619.98 | J8: 450 | K8: 0 | L8: =+E8+B8 -> 5520 | M8: 0 | N8: =SUM(E8-K8) -> 3720
A9: =+A8+1 -> 46149 | B9: 500 | C9: 970 | D9: 0 | E9: 970 | F9: =+E9-(E9*3.99/100) -> 931.297 | G9: =SUM(D9-B9) -> -500 | H9: =SUM(E9-C9) -> 0 | I9: 161.67 | J9: 720 | K9: 0 | L9: =+E9+B9 -> 1470 | M9: =SUM(B9-J9) -> -220 | N9: =SUM(E9-K9) -> 970
A10: =+A9+1 -> 46150 | B10: 1450 | C10: 4550 | D10: 0 | E10: 4550 | F10: =+E10-(E10*3.99/100) -> 4368.455 | G10: =SUM(D10-B10) -> -1450 | H10: =SUM(E10-C10) -> 0 | I10: 666.67 | J10: 170 | K10: 0 | L10: =+E10+B10 -> 6000 | M10: =SUM(B10-J10) -> 1280 | N10: =SUM(E10-K10) -> 4550
A11: =+A10+1 -> 46151 | B11: 1250 | C11: 6550 | D11: 0 | E11: 6550 | F11: =+E11-(E11*3.99/100) -> 6288.655 | G11: =SUM(D11-B11) -> -1250 | H11: =SUM(E11-C11) -> 0 | I11: 1091.66 | J11: 6800 | K11: 32185 | L11: =+E11+B11 -> 7800 | M11: =SUM(B11-J11) -> -5550 | N11: =SUM(E11-K11) -> -25635
A12: =+A11+1 -> 46152 | B12: 600 | C12: 5120 | D12: 0 | E12: 5120 | F12: =+E12-(E12*3.99/100) -> 4915.712 | G12: =SUM(D12-B12) -> -600 | H12: =SUM(E12-C12) -> 0 | I12: 853.33 | J12: 0 | K12: 0 | L12: =+E12+B12 -> 5720 | M12: =SUM(B12-J12) -> 600 | N12: =SUM(E12-K12) -> 5120
A13: =+A12+1 -> 46153 | B13: 800 | C13: 2785 | D13: 0 | E13: 2785 | F13: =+E13-(E13*3.99/100) -> 2673.8785 | G13: =SUM(D13-B13) -> -800 | H13: =SUM(E13-C13) -> 0 | I13: 464.16 | J13: 12350 | K13: 1500 | L13: =+E13+B13 -> 3585 | M13: =SUM(B13-J13) -> -11550 | N13: =SUM(E13-K13) -> 1285
A14: =+A13+1 -> 46154 | B14: 100 | C14: 1720 | D14: 0 | E14: 1720 | F14: =+E14-(E14*3.99/100) -> 1651.372 | G14: =SUM(D14-B14) -> -100 | H14: =SUM(E14-C14) -> 0 | I14: 286.67 | J14: 0 | K14: 3090 | L14: =+E14+B14 -> 1820 | M14: =SUM(B14-J14) -> 100 | N14: =SUM(E14-K14) -> -1370
A15: =+A14+1 -> 46155 | B15: 2060 | C15: 3550 | D15: 0 | E15: 3550 | F15: =+E15-(E15*3.99/100) -> 3408.355 | G15: =SUM(D15-B15) -> -2060 | H15: =SUM(E15-C15) -> 0 | I15: 591.67 | J15: 340 | K15: 0 | L15: =+E15+B15 -> 5610 | M15: =SUM(B15-J15) -> 1720 | N15: =SUM(E15-K15) -> 3550
A16: =+A15+1 -> 46156 | B16: 4100 | C16: 5313 | D16: 0 | E16: 5313 | F16: =+E16-(E16*3.99/100) -> 5101.0113 | G16: =SUM(D16-B16) -> -4100 | H16: =SUM(E16-C16) -> 0 | I16: 885.49 | J16: 0 | K16: 0 | L16: =+E16+B16 -> 9413 | M16: =SUM(B16-J16) -> 4100 | N16: =SUM(E16-K16) -> 5313
A17: =+A16+1 -> 46157 | B17: 4770 | C17: =4920+1260 -> 6180 | D17: 0 | E17: 6180 | F17: =+E17-(E17*3.99/100) -> 5933.418 | G17: =SUM(D17-B17) -> -4770 | H17: =SUM(E17-C17) -> 0 | I17: 1029.97 | J17: 0 | K17: 0 | L17: =+E17+B17 -> 10950 | M17: =SUM(B17-J17) -> 4770 | N17: =SUM(E17-K17) -> 6180
A18: =+A17+1 -> 46158 | B18: 5150 | C18: 8050 | D18: 0 | E18: 8050 | F18: =+E18-(E18*3.99/100) -> 7728.805 | G18: =SUM(D18-B18) -> -5150 | H18: =SUM(E18-C18) -> 0 | I18: 1341.66 | J18: 0 | K18: 0 | L18: =+E18+B18 -> 13200 | M18: =SUM(B18-J18) -> 5150 | N18: =SUM(E18-K18) -> 8050
A19: =+A18+1 -> 46159 | B19: 400 | C19: 3310 | D19: 0 | E19: 3310 | F19: =+E19-(E19*3.99/100) -> 3177.931 | G19: =SUM(D19-B19) -> -400 | H19: =SUM(E19-C19) -> 0 | I19: 551.67 | J19: 0 | K19: 1125 | L19: =+E19+B19 -> 3710 | M19: =SUM(B19-J19) -> 400 | N19: =SUM(E19-K19) -> 2185
A20: =+A19+1 -> 46160 | B20: 600 | C20: 2440 | D20: 0 | E20: 2440 | F20: =+E20-(E20*3.99/100) -> 2342.644 | G20: =SUM(D20-B20) -> -600 | H20: =SUM(E20-C20) -> 0 | I20: 406.67 | J20: 350 | K20: 2008 | L20: =+E20+B20 -> 3040 | M20: =SUM(B20-J20) -> 250 | N20: =SUM(E20-K20) -> 432
A21: =+A20+1 -> 46161 | B21: 400 | C21: 1750 | D21: 0 | E21: 1750 | F21: =+E21-(E21*3.99/100) -> 1680.175 | G21: =SUM(D21-B21) -> -400 | H21: =SUM(E21-C21) -> 0 | I21: 291.66 | J21: 550 | K21: 2220 | L21: =+E21+B21 -> 2150 | M21: =SUM(B21-J21) -> -150 | N21: =SUM(E21-K21) -> -470 | R21: 5
A22: =+A21+1 -> 46162 | B22: 550 | C22: 3400 | D22: 0 | E22: 3400 | F22: =+E22-(E22*3.99/100) -> 3264.34 | G22: =SUM(D22-B22) -> -550 | H22: =SUM(E22-C22) -> 0 | I22: 566.66 | J22: 0 | K22: 1505 | L22: =+E22+B22 -> 3950 | M22: =SUM(B22-J22) -> 550 | N22: =SUM(E22-K22) -> 1895
A23: =+A22+1 -> 46163 | B23: 850 | C23: 4420 | D23: 0 | E23: 4420 | F23: =+E23-(E23*3.99/100) -> 4243.642 | G23: =SUM(D23-B23) -> -850 | H23: =SUM(E23-C23) -> 0 | I23: 767.5 | J23: 50 | K23: 3100 | L23: =+E23+B23 -> 5270 | M23: =SUM(B23-J23) -> 800 | N23: =SUM(E23-K23) -> 1320
A24: =+A23+1 -> 46164 | B24: 2100 | C24: 2210 | D24: 0 | E24: 2210 | F24: =+E24-(E24*3.99/100) -> 2121.821 | G24: =SUM(D24-B24) -> -2100 | H24: =SUM(E24-C24) -> 0 | I24: 393.34 | J24: 250 | K24: 0 | L24: =+E24+B24 -> 4310 | M24: =SUM(B24-J24) -> 1850 | N24: =SUM(E24-K24) -> 2210
A25: 23 Mayıs 2026 Cumartesi | B25: 620 | C25: 2030 | D25: 0 | E25: 2030 | F25: =+E25-(E25*3.99/100) -> 1949.003 | G25: =SUM(D25-B25) -> -620 | H25: =SUM(E25-C25) -> 0 | I25: 338.32 | J25: 0 | K25: 0 | L25: =+E25+B25 -> 2650 | M25: =SUM(B25-J25) -> 620 | N25: =SUM(E25-K25) -> 2030
A26: 24 Mayıs 2026 Cumartesi | B26: 0 | C26: 2880 | D26: 0 | E26: 2880 | F26: =+E26-(E26*3.99/100) -> 2765.088 | G26: =SUM(D26-B26) -> 0 | H26: =SUM(E26-C26) -> 0 | I26: 480 | J26: 19150 | K26: 32700 | L26: =+E26+B26 -> 2880 | M26: =SUM(B26-J26) -> -19150 | N26: =SUM(E26-K26) -> -29820
A27: 25 Mayıs 2026 Cumartesi | B27: 500 | C27: 4540 | D27: 0 | E27: 4540 | F27: =+E27-(E27*3.99/100) -> 4358.854 | G27: =SUM(D27-B27) -> -500 | H27: =SUM(E27-C27) -> 0 | I27: 473.33 | J27: 0 | K27: 0 | L27: =+E27+B27 -> 5040 | M27: =SUM(B27-J27) -> 500 | N27: =SUM(E27-K27) -> 4540
A28: 26 Mayıs 2026 Cumartesi | B28: 300 | C28: 5180 | D28: 0 | E28: 6730 | F28: =+E28-(E28*3.99/100) -> 6461.473 | G28: =SUM(D28-B28) -> -300 | H28: =SUM(E28-C28) -> 1550 | I28: 863.33 | J28: 0 | K28: 0 | L28: =+E28+B28 -> 7030 | M28: =SUM(B28-J28) -> 300 | N28: =SUM(E28-K28) -> 6730
A29: 27 Mayıs 2026 Cumartesi | B29: 0 | C29: 0 | D29: 0 | E29: 0 | F29: =+E29-(E29*3.99/100) -> 0 | G29: =SUM(D29-B29) -> 0 | H29: =SUM(E29-C29) -> 0 | I29: 0 | J29: 200 | K29: 0 | L29: =+E29+B29 -> 0 | M29: =SUM(B29-J29) -> -200 | N29: =SUM(E29-K29) -> 0
A30: 28 Mayıs 2026 Cumartesi | B30: 0 | C30: 0 | D30: 0 | E30: 0 | F30: =+E30-(E30*3.99/100) -> 0 | G30: =SUM(D30-B30) -> 0 | H30: =SUM(E30-C30) -> 0 | I30: 0 | J30: 0 | K30: 4000 | L30: =+E30+B30 -> 0 | M30: =SUM(B30-J30) -> 0 | N30: =SUM(E30-K30) -> -4000
A31: 29 Mayıs 2026 Cumartesi | B31: 600 | C31: 750 | D31: 0 | E31: 750 | F31: =+E31-(E31*3.99/100) -> 720.075 | G31: =SUM(D31-B31) -> -600 | H31: =SUM(E31-C31) -> 0 | I31: 125 | J31: 0 | K31: 0 | L31: =+E31+B31 -> 1350 | M31: =SUM(B31-J31) -> 600 | N31: =SUM(E31-K31) -> 750
A32: 30 Mayıs 2026 Cumartesi | B32: 1100 | C32: 2850 | D32: 0 | E32: 2850 | F32: =+E32-(E32*3.99/100) -> 2736.285 | G32: =SUM(D32-B32) -> -1100 | H32: =SUM(E32-C32) -> 0 | J32: 550 | K32: 0 | L32: =+E32+B32 -> 3950 | M32: =SUM(B32-J32) -> 550 | N32: =SUM(E32-K32) -> 2850
A33: 31 Mayıs 2026 Cumartesi | B33: 620 | C33: 200 | D33: 0 | E33: 200 | F33: =+E33-(E33*3.99/100) -> 192.02 | G33: =SUM(D33-B33) -> -620 | H33: =SUM(E33-C33) -> 0 | I33: 33.33 | J33: 0 | K33: 0 | L33: =+E33+B33 -> 820 | M33: =SUM(B33-J33) -> 620 | N33: =SUM(E33-K33) -> 200
A34: TOPLAM | B34: =SUM(B3:B33) -> 34550 | C34: =SUM(C3:C33) -> 96788 | D34: =SUM(D3:D33) -> 0 | E34: =SUM(E3:E33) -> 98338 | F34: =+E34-(E34*3.99/100) -> 94414.314 | G34: =SUM(G3:G32) -> -33930 | H34: =SUM(H3:H32) -> 1550 | I34: =SUM(I3:I33) -> 15337.09 | J34: =SUM(J3:J33) -> 42830 | K34: =SUM(K3:K33) -> 85203 | L34: =SUM(L3:L32) -> 132068 | M34: =SUM(M3:M32) -> -10250 | N34: =SUM(N3:N32) -> 12935
E35: KESİNTİ | F35: =+E34-F34 -> 3923.6862 | L35: =AVERAGE(L3:L32) -> 4402.2667
H37: TOPLAM CİRO | J37: =SUM(L3:L32) -> 132068
H38: TOPLAM HARCAMA | J38: =SUM(+J34+K34) -> 128033
H39: TOPLAM CİRODAN KALAN | J39: =SUM(M34+N34) -> 2685

Sheet NİSAN 2026
A2: SATIŞ | B2: NAKİT SATIŞ | C2: KREDİ SATIŞ | D2: Z RAPORU NAKİT | E2: Z RAPORU KREDİ | F2: YATACAK OLAN | G2: NAKİT FARK | H2: KREDİ FARK | I2: KDV | J2: NAKİT HARCAMA | K2: KREDİ HARCAMA | L2: CİRO | M2: CEP NAKİT | N2: CEP KREDİ
A3: 46113 | B3: 470 | C3: 2100 | D3: 0 | E3: 2100 | F3: =+E3-(E3*3.99/100) -> 2016.21 | G3: =SUM(D3-B3) -> -470 | H3: =SUM(E3-C3) -> 0 | I3: 350 | J3: 0 | K3: 0 | L3: =+E3+B3 -> 2570 | M3: =SUM(B3-J3) -> 470 | N3: =SUM(E3-K3) -> 2100
A4: =+A3+1 -> 46114 | B4: 2000 | C4: 3520 | D4: 470 | E4: =3270+250 -> 3520 | F4: =+E4-(E4*3.99/100) -> 3379.552 | G4: =SUM(D4-B4) -> -1530 | H4: =SUM(E4-C4) -> 0 | I4: 665 | J4: 450 | K4: 0 | L4: =+E4+B4 -> 5520 | M4: =SUM(B4-J4) -> 1550 | N4: =SUM(E4-K4) -> 3520
A5: =+A4+1 -> 46115 | B5: 0 | C5: 8745 | D5: 350 | E5: =8055+690 -> 8745 | F5: =+E5-(E5*3.99/100) -> 8396.0745 | G5: =SUM(D5-B5) -> 350 | H5: =SUM(E5-C5) -> 0 | I5: 1515.85 | J5: 50 | K5: 300 | L5: =+E5+B5 -> 8745 | M5: =SUM(B5-J5) -> -50 | N5: =SUM(E5-K5) -> 8445
A6: =+A5+1 -> 46116 | B6: 1600 | C6: 3765 | D6: 0 | E6: 3765 | F6: =+E6-(E6*3.99/100) -> 3614.7765 | G6: =SUM(D6-B6) -> -1600 | H6: =SUM(E6-C6) -> 0 | I6: 627.5 | J6: 0 | K6: 0 | L6: =+E6+B6 -> 5365 | M6: =SUM(B6-J6) -> 1600 | N6: =SUM(E6-K6) -> 3765
A7: =+A6+1 -> 46117 | B7: 2020 | C7: 4250 | D7: 455 | E7: =3590+660 -> 4250 | F7: =+E7-(E7*3.99/100) -> 4080.425 | G7: =SUM(D7-B7) -> -1565 | H7: =SUM(E7-C7) -> 0 | I7: 784.16 | J7: 0 | K7: 0 | L7: =+E7+B7 -> 6270 | M7: =SUM(B7-J7) -> 2020 | N7: =SUM(E7-K7) -> 4250
A8: =+A7+1 -> 46118 | B8: 3360 | C8: 4210 | D8: 0 | E8: =2520+1690 -> 4210 | F8: =+E8-(E8*3.99/100) -> 4042.021 | G8: =SUM(D8-B8) -> -3360 | H8: =SUM(E8-C8) -> 0 | I8: 701.66 | J8: 400 | K8: 0 | L8: =+E8+B8 -> 7570 | M8: =SUM(B8-J8) -> 2960 | N8: =SUM(E8-K8) -> 4210
A9: =+A8+1 -> 46119 | B9: 1400 | C9: 5910 | D9: 350 | E9: =4040+1870 -> 5910 | F9: =+E9-(E9*3.99/100) -> 5674.191 | G9: =SUM(D9-B9) -> -1050 | H9: =SUM(E9-C9) -> 0 | I9: 1043.33 | J9: 320 | K9: =39000+8000 -> 47000 | L9: =+E9+B9 -> 7310 | M9: =SUM(B9-J9) -> 1080 | N9: =SUM(E9-K9) -> -41090
A10: =+A9+1 -> 46120 | B10: 1200 | C10: 3115 | D10: 300 | E10: 3115 | F10: =+E10-(E10*3.99/100) -> 2990.7115 | G10: =SUM(D10-B10) -> -900 | H10: =SUM(E10-C10) -> 0 | I10: 569.17 | J10: 0 | K10: 3470 | L10: =+E10+B10 -> 4315 | M10: =SUM(B10-J10) -> 1200 | N10: =SUM(E10-K10) -> -355
A11: =+A10+1 -> 46121 | B11: 1115 | C11: 2990 | D11: 165 | E11: 2990 | F11: =+E11-(E11*3.99/100) -> 2870.699 | G11: =SUM(D11-B11) -> -950 | H11: =SUM(E11-C11) -> 0 | I11: 525.83 | J11: 0 | K11: 4245 | L11: =+E11+B11 -> 4105 | M11: =SUM(B11-J11) -> 1115 | N11: =SUM(E11-K11) -> -1255
A12: =+A11+1 -> 46122 | B12: 900 | C12: 2910 | D12: 175 | E12: =2760+150 -> 2910 | F12: =+E12-(E12*3.99/100) -> 2793.891 | G12: =SUM(D12-B12) -> -725 | H12: =SUM(E12-C12) -> 0 | I12: 514.18 | J12: 13700 | K12: 10400 | L12: =+E12+B12 -> 3810 | M12: =SUM(B12-J12) -> -12800 | N12: =SUM(E12-K12) -> -7490
A13: =+A12+1 -> 46123 | B13: 1965 | C13: 3210 | D13: 0 | E13: =2740+470 -> 3210 | F13: =+E13-(E13*3.99/100) -> 3081.921 | G13: =SUM(D13-B13) -> -1965 | H13: =SUM(E13-C13) -> 0 | I13: 534.99 | J13: =90+160+350+100 -> 700 | K13: 0 | L13: =+E13+B13 -> 5175 | M13: =SUM(B13-J13) -> 1265 | N13: =SUM(E13-K13) -> 3210
A14: =+A13+1 -> 46124 | B14: 1650 | C14: 2560 | D14: 0 | E14: =2190+370 -> 2560 | F14: =+E14-(E14*3.99/100) -> 2457.856 | G14: =SUM(D14-B14) -> -1650 | H14: =SUM(E14-C14) -> 0 | I14: 426.67 | J14: 0 | K14: 550 | L14: =+E14+B14 -> 4210 | M14: =SUM(B14-J14) -> 1650 | N14: =SUM(E14-K14) -> 2010
A15: =+A14+1 -> 46125 | B15: 200 | C15: 1960 | D15: 0 | E15: 1960 | F15: =+E15-(E15*3.99/100) -> 1881.796 | G15: =SUM(D15-B15) -> -200 | H15: =SUM(E15-C15) -> 0 | I15: 326.67 | J15: =5000+105+115 -> 5220 | K15: =2000+5525 -> 7525 | L15: =+E15+B15 -> 2160 | M15: =SUM(B15-J15) -> -5020 | N15: =SUM(E15-K15) -> -5565
A16: =+A15+1 -> 46126 | B16: 350 | C16: 1765 | D16: 100 | E16: =1245+520 -> 1765 | F16: =+E16-(E16*3.99/100) -> 1694.5765 | G16: =SUM(D16-B16) -> -250 | H16: =SUM(E16-C16) -> 0 | I16: 310.84 | J16: 1950 | K16: =1620+760 -> 2380 | L16: =+E16+B16 -> 2115 | M16: =SUM(B16-J16) -> -1600 | N16: =SUM(E16-K16) -> -615
A17: =+A16+1 -> 46127 | B17: 900 | C17: 5090 | D17: 330 | E17: =4590+500 -> 5090 | F17: =+E17-(E17*3.99/100) -> 4886.909 | G17: =SUM(D17-B17) -> -570 | H17: =SUM(E17-C17) -> 0 | I17: 903.33 | J17: 0 | K17: 0 | L17: =+E17+B17 -> 5990 | M17: =SUM(B17-J17) -> 900 | N17: =SUM(E17-K17) -> 5090
A18: =+A17+1 -> 46128 | B18: 500 | C18: 6630 | D18: 155 | E18: 6630 | F18: =+E18-(E18*3.99/100) -> 6365.463 | G18: =SUM(D18-B18) -> -345 | H18: =SUM(E18-C18) -> 0 | I18: 1130.82 | J18: 90 | K18: =5280+800 -> 6080 | L18: =+E18+B18 -> 7130 | M18: =SUM(B18-J18) -> 410 | N18: =SUM(E18-K18) -> 550
A19: =+A18+1 -> 46129 | B19: 800 | C19: =270+1005 -> 1275 | D19: 0 | E19: =885+120 -> 1005 | F19: =+E19-(E19*3.99/100) -> 964.9005 | G19: =SUM(D19-B19) -> -800 | H19: =SUM(E19-C19) -> -270 | I19: 167.5 | J19: 0 | K19: 4655 | L19: =+E19+B19 -> 1805 | M19: =SUM(B19-J19) -> 800 | N19: =SUM(E19-K19) -> -3650
A20: =+A19+1 -> 46130 | B20: 1600 | C20: =1580+2350 -> 3930 | D20: 85 | E20: =980+600 -> 1580 | F20: =+E20-(E20*3.99/100) -> 1516.958 | G20: =SUM(D20-B20) -> -1515 | H20: =SUM(E20-C20) -> -2350 | I20: 277.5 | J20: 215 | K20: 240 | L20: =+E20+B20 -> 3180 | M20: =SUM(B20-J20) -> 1385 | N20: =SUM(E20-K20) -> 1340
A21: =+A20+1 -> 46131 | B21: 1300 | C21: 900 | D21: 100 | E21: 900 | F21: =+E21-(E21*3.99/100) -> 864.09 | G21: =SUM(D21-B21) -> -1200 | H21: =SUM(E21-C21) -> 0 | I21: 166.67 | J21: 250 | K21: 0 | L21: =+E21+B21 -> 2200 | M21: =SUM(B21-J21) -> 1050 | N21: =SUM(E21-K21) -> 900
